Workbook
Name BaseMonths: Settings!$B$7:$B$7
Name BaseVersion: Settings!$B$9
Name CurrentMonths: Settings!$B$8:$B$8
Name CurrentVersion: Settings!$B$10
Name Threshold: Settings!$B$11
Name TotalBase: Summary!$A$5
Name TotalCurrent: Summary!$B$5

Sheet Summary
A1: Untitled analysis
A2: Jul 2026 compared with Jun 2026 · Prepared 28 Oct 2026 14:23 UTC
A4: Base total | B4: Current total | C4: Movement | D4: Movement % | E4: Threshold
A5: =SUMPRODUCT((ISNUMBER(MATCH(Data!$D$2:$D$666,BaseMonths,0)))*Data!$E$2:$E$666) -> 27160793 | B5: =SUMPRODUCT((ISNUMBER(MATCH(Data!$D$2:$D$666,CurrentMonths,0)))*Data!$E$2:$E$666) -> 21173166 | C5: =B5-A5 -> -5987626.9 | D5: =IF(A5=0,"",C5/ABS(A5)) -> -0.22045111 | E5: =Threshold -> 300000
A7: Explanation status
A8: Needs explanation | B8: Explained by AI — please review | C8: Confirmed | D8: Below threshold
A9: =COUNTIF(Commentary!$J$2:$J$7,"Needs explanation") -> 5 | B9: =COUNTIF(Commentary!$J$2:$J$7,"Explained by AI — please review") -> 0 | C9: =COUNTIF(Commentary!$J$2:$J$7,"Confirmed") -> 0 | D9: =COUNTIF(Commentary!$J$2:$J$7,"Below threshold") -> 1
A10: 5 movements still need a person to write or check the explanation — open Needs Explanation
A12: Headline
A13: -$0.4M — Brazil / AMER / SP3. [TO VERIFY] Confirm the business cause.
A15: Key drivers
A16: Movement | B16: Base | C16: Current | D16: Change | E16: Change % | F16: Status | G16: Explanation
A17: Brazil / AMER / SP3 | B17: ='Commentary'!$E$2 -> 440441.66 | C17: ='Commentary'!$F$2 -> -2367.7 | D17: ='Commentary'!$G$2 -> -442809.36 | E17: =IF(B17=0,"",D17/ABS(B17)) -> -1.0053757 | F17: Needs explanation | G17: -$0.4M — Brazil / AMER / SP3. [TO VERIFY] Confirm the business cause.
A18: Germany / EMEA / FR2 | B18: ='Commentary'!$E$3 -> 1128962 | C18: ='Commentary'!$F$3 -> 704639.62 | D18: ='Commentary'!$G$3 -> -424322.34 | E18: =IF(B18=0,"",D18/ABS(B18)) -> -0.37585176 | F18: Needs explanation | G18: -$0.4M — Germany / EMEA / FR2. [TO VERIFY] Confirm the business cause.
A19: United States / AMER / DC12 | B19: ='Commentary'!$E$4 -> 716637.09 | C19: ='Commentary'!$F$4 -> 321587.31 | D19: ='Commentary'!$G$4 -> -395049.78 | E19: =IF(B19=0,"",D19/ABS(B19)) -> -0.551255 | F19: Needs explanation | G19: -$0.4M — United States / AMER / DC12. [TO VERIFY] Confirm the business cause.
A20: United States / AMER / NY7 | B20: ='Commentary'!$E$5 -> 285390.86 | C20: ='Commentary'!$F$5 -> -88890.38 | D20: ='Commentary'!$G$5 -> -374281.24 | E20: =IF(B20=0,"",D20/ABS(B20)) -> -1.3114689 | F20: Needs explanation | G20: -$0.4M — United States / AMER / NY7. [TO VERIFY] Confirm the business cause.
A21: Singapore / APAC / SG4 | B21: ='Commentary'!$E$6 -> 144966.12 | C21: ='Commentary'!$F$6 -> 448730.36 | D21: ='Commentary'!$G$6 -> 303764.24 | E21: =IF(B21=0,"",D21/ABS(B21)) -> 2.0954154 | F21: Needs explanation | G21: +$0.3M — Singapore / APAC / SG4. [TO VERIFY] Confirm the business cause.
A22: Other items | B22: ='Commentary'!$E$7 -> 24444396 | C22: ='Commentary'!$F$7 -> 19789467 | D22: ='Commentary'!$G$7 -> -4654928.5 | E22: =IF(B22=0,"",D22/ABS(B22)) -> -0.19042927 | F22: Below threshold | G22: -$4.7M — Other items. [TO VERIFY] Confirm the business cause.
A24: What is in this workbook
A25: Review
A26: Summary | B26: This overview: totals, explanation status, key drivers and a guide to the tabs.
A27: Needs Explanation | B27: Movements that still need a person to write or check the explanation.
A28: Commentary | B28: Every reported movement with its amounts, status, explanation and who confirmed it.
A30: Evidence and reconciliation
A31: Drill-down | B31: Every line of the comparison, largest change first, and which movement it is reported in.
A32: Data checks | B32: Reconciliation: the workbook's formulas must agree with the engine's totals.
A33: Data | B33: The grouped source amounts every formula adds up.
A34: Settings | B34: Months, versions and the threshold the formulas use. Change Threshold to test sensitivity.
A36: Supporting detail
A37: Variance - By country | B37: Every line of the 'By country' comparison, as calculated by the engine.
A38: Movement detail | B38: Each reported movement with its grouping, line count, flags and evidence references.
A39: Source lines | B39: The source descriptions behind each movement, with their amounts.
A40: Classifications | B40: How lines were classified, for review.
A41: Unmatched lookups | B41: Lookup values that did not match the main data.
A43: Audit trail
A44: Data controls | B44: Every data control run before the report, with its details.
A45: Setup changes | B45: Every change made to the setup before this run, with who made it and why.
A46: Explanation log | B46: Every explanation saved or confirmed, with who did it and when.
A47: Run audit | B47: Run fingerprint: engine version, setup fingerprint and the fingerprint of every input file.
A48: AI assistant log | B48: What the AI assistant was asked and answered while building this report.
...

Sheet Needs Explanation
A1: Movement | B1: Change | C1: Base | D1: Current | E1: Status | F1: Current text | G1: What is needed | H1: Supporting descriptions
A2: Brazil / AMER / SP3 | B2: ='Commentary'!$G$2 -> -442809.36 | C2: ='Commentary'!$E$2 -> 440441.66 | D2: ='Commentary'!$F$2 -> -2367.7 | E2: Needs explanation | F2: -$0.4M — Brazil / AMER / SP3. [TO VERIFY] Confirm the business cause. | G2: Write the business reason and confirm it. | H2: GAO6111_AP_0626_AMER Manual Acc_A5-NoXZSEfGJGSVu_9IVgQ-300000131614726-ACCR-100002823917343 , VERTIV TECNOLOGIA DO BRASIL LTDA|R&M , 8002 , 14429487 (-$0.1M); GAO6111_AP_0626_AMER Manual Acc_A5-NoXZSEfGJGSVu_9IVgQ-300000131614726-ACCR-100002823917343 , VERTIV TECNOLOGIA DO BRASIL LTDA|R&M , 8002 , 14429488 (-$0.1M); GAO5203_MD_0626_OpenPOCath_lnw3d3VcEfGJGSVu_9IVgQ-300000131614726-ACCR-100002819269393 , 1110592271-1_VERTIV TECNOLOGIA DO BRASIL LTDA_SP3 Vertiv as per amendm (-$0.1M); GAO5203_MD_0626_OpenPOCath_lnw3d3VcEfGJGSVu_9IVgQ-300000131614726-ACCR-100002819269393 , 1110592271-1_VERTIV TECNOLOGIA DO BRASIL LTDA_SP3 Vertiv as per amendm (-$0.1M); PO Number: 1110572259 , PO Line Number: 1 ,Supplier Name: CUMMINS VENDAS E SERVICOS DE MOTORES E GERADORES LTDA Invoice Number: 343422-4-20260521-61838884000142 (-$36,053.72)
A3: Germany / EMEA / FR2 | B3: ='Commentary'!$G$3 -> -424322.34 | C3: ='Commentary'!$E$3 -> 1128962 | D3: ='Commentary'!$F$3 -> 704639.62 | E3: Needs explanation | F3: -$0.4M — Germany / EMEA / FR2. [TO VERIFY] Confirm the business cause. | G3: Write the business reason and confirm it. | H3: GAO5049_KB_0526_OpenPO WW_VHUHT1qnEfGpxZVkiKiA2g-300000131614726-ACCR-100002737255229 , 1590535725-2_ACTEMIUM CEGELEC GMBH_FR2.1-6 2026 Q2 maintenance of fire m (+$0.1M); PO Number: 1590535725 , PO Line Number: 2 ,Supplier Name: ACTEMIUM CEGELEC GMBH Invoice Number: 1870021642 Description: FR2.1-6 2026 Q2 maintenance of fire moni (-$0.1M); GAO5049_KB_0526_OpenPO WW_VHUHT1qnEfGpxZVkiKiA2g-300000131614726-ACCR-100002737255229 , 1590566063-1_SOCOMEC GMBH_FR2 Impedance measurement Semi Annual Maintena (+$0.1M); PO Number: 1590566063 , PO Line Number: 1 ,Supplier Name: SOCOMEC GMBH Invoice Number: 800 / 31256535 Description: FR2 Impedance measurement Semi Annual Mainten (-$0.1M); GAO5049_KB_0626_OpenPO WW_5MUniXOlEfGxWZ1NRsFAkA-300000131614726-ACCR-100002808784117 , 1590548361-1_HEINRICH BOLLMANN GMBH_FR2 - 2026 Sachkundigenprfung und Wa (-$0.1M)
A4: United States / AMER / DC12 | B4: ='Commentary'!$G$4 -> -395049.78 | C4: ='Commentary'!$E$4 -> 716637.09 | D4: ='Commentary'!$F$4 -> 321587.31 | E4: Needs explanation | F4: -$0.4M — United States / AMER / DC12. [TO VERIFY] Confirm the business cause. | G4: Write the business reason and confirm it. | H4: GAO5049_KB_0626_OpenPO WW_5MUniXOlEfGxWZ1NRsFAkA-300000131614726-ACCR-100002809437203 , 1040590899-1_EBM PAPST INC US CT FARMI IV 456_DC12-EBMPAPST as per quote (-$0.2M); GAO5049_KB_0626_OpenPO WW_5MUniXOlEfGxWZ1NRsFAkA-300000131614726-ACCR-100002809437203 , 1040590899-1_EBM PAPST INC US CT FARMI IV 456_DC12-EBMPAPST as per quote (-$0.2M); GAO5049_KB_0726_OpenPO WW_M3Z9-4xYEfGhDpMHE24o3Q-300000131614726-ACCR-100002877409113 , 1040590899-1_EBM PAPST INC US CT FARMI IV 456_DC12-EBMPAPST as per quote (+$0.2M); GAO5049_KB_0526_OpenPO WW_VHUHT1qnEfGpxZVkiKiA2g-300000131614726-ACCR-100002737453098 , 1040543939-1_EBM PAPST INC US CT FARMI IV 456_DC12: Supply Fan Part #R3G (+$0.2M); GAO5049_KB_0626_OpenPO WW_5MUniXOlEfGxWZ1NRsFAkA-300000131614726-ACCR-100002809437203 , 1040543939-1_EBM PAPST INC US CT FARMI IV 456_DC12: Supply Fan Part #R3G (-$0.2M)
A5: United States / AMER / NY7 | B5: ='Commentary'!$G$5 -> -374281.24 | C5: ='Commentary'!$E$5 -> 285390.86 | D5: ='Commentary'!$F$5 -> -88890.38 | E5: Needs explanation | F5: -$0.4M — United States / AMER / NY7. [TO VERIFY] Confirm the business cause. | G5: Write the business reason and confirm it. | H5: PO Number: 1040573824 , PO Line Number: 2 ,Supplier Name: CARRIER CORPORATION Invoice Number: 90543992 Description: NY7: Labor per Carrier quote dated 04/06/202 (-$29,362.39); PO Number: 1040566040 , PO Line Number: 2 ,Supplier Name: ORR PROTECTION SYSTEMS INC Invoice Number: IN-0086444 Description: NY7: Q2 2026 - Orr Fire protection (+$22,124.69); GAO5049_KB_0526_OpenPO WW_VHUHT1qnEfGpxZVkiKiA2g-300000131614726-ACCR-100002737453098 , 1040457223-1_NALCO COMPANY FKA ONDEO NALCO COMPANY_NY7 $41032.14-BPO Che (+$19,142.64); GAO5049_KB_0626_OpenPO WW_5MUniXOlEfGxWZ1NRsFAkA-300000131614726-ACCR-100002809437203 , 1040457223-1_NALCO COMPANY FKA ONDEO NALCO COMPANY_NY7 $41032.14-BPO Che (-$19,142.64)
A6: Singapore / APAC / SG4 | B6: ='Commentary'!$G$6 -> 303764.24 | C6: ='Commentary'!$E$6 -> 144966.12 | D6: ='Commentary'!$F$6 -> 448730.36 | E6: Needs explanation | F6: +$0.3M — Singapore / APAC / SG4. [TO VERIFY] Confirm the business cause. | G6: Write the business reason and confirm it. | H6: PO Number: 1400559725 , PO Line Number: 1 ,Supplier Name: EATON ELECTRIC SINGAPORE PTE LTD Invoice Number: 957921169 Description: UPS Model: Eaton 9395P-1200kVA (+$0.1M); GAO5153_NS_0726_OpePO APACRe_K1IRko2YEfGhDpMHE24o3Q-300000131614726-ACCR-100002883223886 , 1400585681-1_ROCKWELL AUTOMATION SOUTHEAST ASIA PTE LIMITED_SG4 CPOS (+$0.1M); PO Number: 1400583089 , PO Line Number: 1 ,Supplier Name: LC ENGINEERING SERVICES PTE LTD Invoice Number: 26/J-1333/I-29468 Description: SG4 Level 1/2/3/4/5/7. (+$0.1M); GAO5153_NS_0726_OpePO APACRe_K1IRko2YEfGhDpMHE24o3Q-300000131614726-ACCR-100002883223886 , 1400559720-1_EATON ELECTRIC SINGAPORE PTE LTD_SN1 Non Comprehensive M (+$38,693.52); GAO5153_NS_0626_OpePO APACRe_xG9IjHShEfGxWZ1NRsFAkA-300000131614726-ACCR-100002813198521 , 1400559720-1_EATON ELECTRIC SINGAPORE PTE LTD_SN1 Non Comprehensive M (-$33,623.26)

Sheet Commentary
A1: Movement | B1: Country | C1: Region | D1: Ibx_Code | E1: Base | F1: Current | G1: Change | H1: Change % | I1: Above threshold? | J1: Status | K1: Explanation | L1: Written by | M1: Confirmed by | N1: Confirmed (UTC) | O1: Evidence
A2: Brazil / AMER / SP3 | B2: Brazil | C2: AMER | D2: SP3 | E2: =SUMPRODUCT((Data!$A$2:$A$666=$B2)*(Data!$B$2:$B$666=$C2)*(Data!$C$2:$C$666=$D2)*(ISNUMBER(MATCH(Data!$D$2:$D$666,BaseMonths,0)))*Data!$E$2:$E$666) -> 440441.66 | F2: =SUMPRODUCT((Data!$A$2:$A$666=$B2)*(Data!$B$2:$B$666=$C2)*(Data!$C$2:$C$666=$D2)*(ISNUMBER(MATCH(Data!$D$2:$D$666,CurrentMonths,0)))*Data!$E$2:$E$666) -> -2367.7 | G2: =F2-E2 -> -442809.36 | H2: =IF(E2=0,"",G2/ABS(E2)) -> -1.0053757 | I2: =IF(ABS(G2)>=Threshold,"Yes","No") -> Yes | J2: Needs explanation | K2: -$0.4M — Brazil / AMER / SP3. [TO VERIFY] Confirm the business cause. | L2: Placeholder | O2: GAO6111_AP_0626_AMER Manual Acc_A5-NoXZSEfGJGSVu_9IVgQ-300000131614726-ACCR-100002823917343 , VERTIV TECNOLOGIA DO BRASIL LTDA|R&M , 8002 , 14429487 (-$0.1M); GAO6111_AP_0626_AMER Manual Acc_A5-NoXZSEfGJGSVu_9IVgQ-300000131614726-ACCR-100002823917343 , VERTIV TECNOLOGIA DO BRASIL LTDA|R&M , 8002 , 14429488 (-$0.1M); GAO5203_MD_0626_OpenPOCath_lnw3d3VcEfGJGSVu_9IVgQ-300000131614726-ACCR-100002819269393 , 1110592271-1_VERTIV TECNOLOGIA DO BRASIL LTDA_SP3 Vertiv as per amendm (-$0.1M); GAO5203_MD_0626_OpenPOCath_lnw3d3VcEfGJGSVu_9IVgQ-300000131614726-ACCR-100002819269393 , 1110592271-1_VERTIV TECNOLOGIA DO BRASIL LTDA_SP3 Vertiv as per amendm (-$0.1M); PO Number: 1110572259 , PO Line Number: 1 ,Supplier Name: CUMMINS VENDAS E SERVICOS DE MOTORES E GERADORES LTDA Invoice Number: 343422-4-20260521-61838884000142 (-$36,053.72)
A3: Germany / EMEA / FR2 | B3: Germany | C3: EMEA | D3: FR2 | E3: =SUMPRODUCT((Data!$A$2:$A$666=$B3)*(Data!$B$2:$B$666=$C3)*(Data!$C$2:$C$666=$D3)*(ISNUMBER(MATCH(Data!$D$2:$D$666,BaseMonths,0)))*Data!$E$2:$E$666) -> 1128962 | F3: =SUMPRODUCT((Data!$A$2:$A$666=$B3)*(Data!$B$2:$B$666=$C3)*(Data!$C$2:$C$666=$D3)*(ISNUMBER(MATCH(Data!$D$2:$D$666,CurrentMonths,0)))*Data!$E$2:$E$666) -> 704639.62 | G3: =F3-E3 -> -424322.34 | H3: =IF(E3=0,"",G3/ABS(E3)) -> -0.37585176 | I3: =IF(ABS(G3)>=Threshold,"Yes","No") -> Yes | J3: Needs explanation | K3: -$0.4M — Germany / EMEA / FR2. [TO VERIFY] Confirm the business cause. | L3: Placeholder | O3: GAO5049_KB_0526_OpenPO WW_VHUHT1qnEfGpxZVkiKiA2g-300000131614726-ACCR-100002737255229 , 1590535725-2_ACTEMIUM CEGELEC GMBH_FR2.1-6 2026 Q2 maintenance of fire m (+$0.1M); PO Number: 1590535725 , PO Line Number: 2 ,Supplier Name: ACTEMIUM CEGELEC GMBH Invoice Number: 1870021642 Description: FR2.1-6 2026 Q2 maintenance of fire moni (-$0.1M); GAO5049_KB_0526_OpenPO WW_VHUHT1qnEfGpxZVkiKiA2g-300000131614726-ACCR-100002737255229 , 1590566063-1_SOCOMEC GMBH_FR2 Impedance measurement Semi Annual Maintena (+$0.1M); PO Number: 1590566063 , PO Line Number: 1 ,Supplier Name: SOCOMEC GMBH Invoice Number: 800 / 31256535 Description: FR2 Impedance measurement Semi Annual Mainten (-$0.1M); GAO5049_KB_0626_OpenPO WW_5MUniXOlEfGxWZ1NRsFAkA-300000131614726-ACCR-100002808784117 , 1590548361-1_HEINRICH BOLLMANN GMBH_FR2 - 2026 Sachkundigenprfung und Wa (-$0.1M)
A4: United States / AMER / DC12 | B4: United States | C4: AMER | D4: DC12 | E4: =SUMPRODUCT((Data!$A$2:$A$666=$B4)*(Data!$B$2:$B$666=$C4)*(Data!$C$2:$C$666=$D4)*(ISNUMBER(MATCH(Data!$D$2:$D$666,BaseMonths,0)))*Data!$E$2:$E$666) -> 716637.09 | F4: =SUMPRODUCT((Data!$A$2:$A$666=$B4)*(Data!$B$2:$B$666=$C4)*(Data!$C$2:$C$666=$D4)*(ISNUMBER(MATCH(Data!$D$2:$D$666,CurrentMonths,0)))*Data!$E$2:$E$666) -> 321587.31 | G4: =F4-E4 -> -395049.78 | H4: =IF(E4=0,"",G4/ABS(E4)) -> -0.551255 | I4: =IF(ABS(G4)>=Threshold,"Yes","No") -> Yes | J4: Needs explanation | K4: -$0.4M — United States / AMER / DC12. [TO VERIFY] Confirm the business cause. | L4: Placeholder | O4: GAO5049_KB_0626_OpenPO WW_5MUniXOlEfGxWZ1NRsFAkA-300000131614726-ACCR-100002809437203 , 1040590899-1_EBM PAPST INC US CT FARMI IV 456_DC12-EBMPAPST as per quote (-$0.2M); GAO5049_KB_0626_OpenPO WW_5MUniXOlEfGxWZ1NRsFAkA-300000131614726-ACCR-100002809437203 , 1040590899-1_EBM PAPST INC US CT FARMI IV 456_DC12-EBMPAPST as per quote (-$0.2M); GAO5049_KB_0726_OpenPO WW_M3Z9-4xYEfGhDpMHE24o3Q-300000131614726-ACCR-100002877409113 , 1040590899-1_EBM PAPST INC US CT FARMI IV 456_DC12-EBMPAPST as per quote (+$0.2M); GAO5049_KB_0526_OpenPO WW_VHUHT1qnEfGpxZVkiKiA2g-300000131614726-ACCR-100002737453098 , 1040543939-1_EBM PAPST INC US CT FARMI IV 456_DC12: Supply Fan Part #R3G (+$0.2M); GAO5049_KB_0626_OpenPO WW_5MUniXOlEfGxWZ1NRsFAkA-300000131614726-ACCR-100002809437203 , 1040543939-1_EBM PAPST INC US CT FARMI IV 456_DC12: Supply Fan Part #R3G (-$0.2M)
A5: United States / AMER / NY7 | B5: United States | C5: AMER | D5: NY7 | E5: =SUMPRODUCT((Data!$A$2:$A$666=$B5)*(Data!$B$2:$B$666=$C5)*(Data!$C$2:$C$666=$D5)*(ISNUMBER(MATCH(Data!$D$2:$D$666,BaseMonths,0)))*Data!$E$2:$E$666) -> 285390.86 | F5: =SUMPRODUCT((Data!$A$2:$A$666=$B5)*(Data!$B$2:$B$666=$C5)*(Data!$C$2:$C$666=$D5)*(ISNUMBER(MATCH(Data!$D$2:$D$666,CurrentMonths,0)))*Data!$E$2:$E$666) -> -88890.38 | G5: =F5-E5 -> -374281.24 | H5: =IF(E5=0,"",G5/ABS(E5)) -> -1.3114689 | I5: =IF(ABS(G5)>=Threshold,"Yes","No") -> Yes | J5: Needs explanation | K5: -$0.4M — United States / AMER / NY7. [TO VERIFY] Confirm the business cause. | L5: Placeholder | O5: PO Number: 1040573824 , PO Line Number: 2 ,Supplier Name: CARRIER CORPORATION Invoice Number: 90543992 Description: NY7: Labor per Carrier quote dated 04/06/202 (-$29,362.39); PO Number: 1040566040 , PO Line Number: 2 ,Supplier Name: ORR PROTECTION SYSTEMS INC Invoice Number: IN-0086444 Description: NY7: Q2 2026 - Orr Fire protection (+$22,124.69); GAO5049_KB_0526_OpenPO WW_VHUHT1qnEfGpxZVkiKiA2g-300000131614726-ACCR-100002737453098 , 1040457223-1_NALCO COMPANY FKA ONDEO NALCO COMPANY_NY7 $41032.14-BPO Che (+$19,142.64); GAO5049_KB_0626_OpenPO WW_5MUniXOlEfGxWZ1NRsFAkA-300000131614726-ACCR-100002809437203 , 1040457223-1_NALCO COMPANY FKA ONDEO NALCO COMPANY_NY7 $41032.14-BPO Che (-$19,142.64)
A6: Singapore / APAC / SG4 | B6: Singapore | C6: APAC | D6: SG4 | E6: =SUMPRODUCT((Data!$A$2:$A$666=$B6)*(Data!$B$2:$B$666=$C6)*(Data!$C$2:$C$666=$D6)*(ISNUMBER(MATCH(Data!$D$2:$D$666,BaseMonths,0)))*Data!$E$2:$E$666) -> 144966.12 | F6: =SUMPRODUCT((Data!$A$2:$A$666=$B6)*(Data!$B$2:$B$666=$C6)*(Data!$C$2:$C$666=$D6)*(ISNUMBER(MATCH(Data!$D$2:$D$666,CurrentMonths,0)))*Data!$E$2:$E$666) -> 448730.36 | G6: =F6-E6 -> 303764.24 | H6: =IF(E6=0,"",G6/ABS(E6)) -> 2.0954154 | I6: =IF(ABS(G6)>=Threshold,"Yes","No") -> Yes | J6: Needs explanation | K6: +$0.3M — Singapore / APAC / SG4. [TO VERIFY] Confirm the business cause. | L6: Placeholder | O6: PO Number: 1400559725 , PO Line Number: 1 ,Supplier Name: EATON ELECTRIC SINGAPORE PTE LTD Invoice Number: 957921169 Description: UPS Model: Eaton 9395P-1200kVA (+$0.1M); GAO5153_NS_0726_OpePO APACRe_K1IRko2YEfGhDpMHE24o3Q-300000131614726-ACCR-100002883223886 , 1400585681-1_ROCKWELL AUTOMATION SOUTHEAST ASIA PTE LIMITED_SG4 CPOS (+$0.1M); PO Number: 1400583089 , PO Line Number: 1 ,Supplier Name: LC ENGINEERING SERVICES PTE LTD Invoice Number: 26/J-1333/I-29468 Description: SG4 Level 1/2/3/4/5/7. (+$0.1M); GAO5153_NS_0726_OpePO APACRe_K1IRko2YEfGhDpMHE24o3Q-300000131614726-ACCR-100002883223886 , 1400559720-1_EATON ELECTRIC SINGAPORE PTE LTD_SN1 Non Comprehensive M (+$38,693.52); GAO5153_NS_0626_OpePO APACRe_xG9IjHShEfGxWZ1NRsFAkA-300000131614726-ACCR-100002813198521 , 1400559720-1_EATON ELECTRIC SINGAPORE PTE LTD_SN1 Non Comprehensive M (-$33,623.26)
A7: Other items | E7: =TotalBase-SUM(E2:E6) -> 24444396 | F7: =TotalCurrent-SUM(F2:F6) -> 19789467 | G7: =F7-E7 -> -4654928.5 | H7: =IF(E7=0,"",G7/ABS(E7)) -> -0.19042927 | I7: Grouped | J7: Below threshold | K7: -$4.7M — Other items. [TO VERIFY] Confirm the business cause. | L7: Placeholder | O7: GAO5049_KB_0526_OpenPO WW_VHUHT1qnEfGpxZVkiKiA2g-300000131614726-ACCR-100002737453098 , 1040525989-2_TAMPA ARMATURE WORKS INC DBA INTEGRATED POWER SERVICES_MI6 (+$0.2M); GAO5049_KB_0626_OpenPO WW_5MUniXOlEfGxWZ1NRsFAkA-300000131614726-ACCR-100002809437203 , 1040525989-2_TAMPA ARMATURE WORKS INC DBA INTEGRATED POWER SERVICES_MI6 (-$0.2M); GAO5049_KB_0626_OpenPO WW_5MUniXOlEfGxWZ1NRsFAkA-300000131614726-ACCR-100002809437203 , 1040525989-2_TAMPA ARMATURE WORKS INC DBA INTEGRATED POWER SERVICES_MI6 (-$0.2M); GAO5049_KB_0726_OpenPO WW_M3Z9-4xYEfGhDpMHE24o3Q-300000131614726-ACCR-100002877409113 , 1040525989-2_TAMPA ARMATURE WORKS INC DBA INTEGRATED POWER SERVICES_MI6 (+$0.2M)

Sheet Drill-down
A1: Country | B1: Region | C1: Ibx_Code | D1: Base | E1: Current | F1: Change | G1: Change % | H1: Above threshold? | I1: Reported as
A2: Brazil | B2: AMER | C2: SP3 | D2: =SUMPRODUCT((Data!$A$2:$A$666=$A2)*(Data!$B$2:$B$666=$B2)*(Data!$C$2:$C$666=$C2)*(ISNUMBER(MATCH(Data!$D$2:$D$666,BaseMonths,0)))*Data!$E$2:$E$666) -> 440441.66 | E2: =SUMPRODUCT((Data!$A$2:$A$666=$A2)*(Data!$B$2:$B$666=$B2)*(Data!$C$2:$C$666=$C2)*(ISNUMBER(MATCH(Data!$D$2:$D$666,CurrentMonths,0)))*Data!$E$2:$E$666) -> -2367.7 | F2: =E2-D2 -> -442809.36 | G2: =IF(D2=0,"",F2/ABS(D2)) -> -1.0053757 | H2: =IF(ABS(F2)>=Threshold,"Yes","No") -> Yes | I2: Brazil / AMER / SP3
A3: Germany | B3: EMEA | C3: FR2 | D3: =SUMPRODUCT((Data!$A$2:$A$666=$A3)*(Data!$B$2:$B$666=$B3)*(Data!$C$2:$C$666=$C3)*(ISNUMBER(MATCH(Data!$D$2:$D$666,BaseMonths,0)))*Data!$E$2:$E$666) -> 1128962 | E3: =SUMPRODUCT((Data!$A$2:$A$666=$A3)*(Data!$B$2:$B$666=$B3)*(Data!$C$2:$C$666=$C3)*(ISNUMBER(MATCH(Data!$D$2:$D$666,CurrentMonths,0)))*Data!$E$2:$E$666) -> 704639.62 | F3: =E3-D3 -> -424322.34 | G3: =IF(D3=0,"",F3/ABS(D3)) -> -0.37585176 | H3: =IF(ABS(F3)>=Threshold,"Yes","No") -> Yes | I3: Germany / EMEA / FR2
A4: United States | B4: AMER | C4: DC12 | D4: =SUMPRODUCT((Data!$A$2:$A$666=$A4)*(Data!$B$2:$B$666=$B4)*(Data!$C$2:$C$666=$C4)*(ISNUMBER(MATCH(Data!$D$2:$D$666,BaseMonths,0)))*Data!$E$2:$E$666) -> 716637.09 | E4: =SUMPRODUCT((Data!$A$2:$A$666=$A4)*(Data!$B$2:$B$666=$B4)*(Data!$C$2:$C$666=$C4)*(ISNUMBER(MATCH(Data!$D$2:$D$666,CurrentMonths,0)))*Data!$E$2:$E$666) -> 321587.31 | F4: =E4-D4 -> -395049.78 | G4: =IF(D4=0,"",F4/ABS(D4)) -> -0.551255 | H4: =IF(ABS(F4)>=Threshold,"Yes","No") -> Yes | I4: United States / AMER / DC12
A5: United States | B5: AMER | C5: NY7 | D5: =SUMPRODUCT((Data!$A$2:$A$666=$A5)*(Data!$B$2:$B$666=$B5)*(Data!$C$2:$C$666=$C5)*(ISNUMBER(MATCH(Data!$D$2:$D$666,BaseMonths,0)))*Data!$E$2:$E$666) -> 285390.86 | E5: =SUMPRODUCT((Data!$A$2:$A$666=$A5)*(Data!$B$2:$B$666=$B5)*(Data!$C$2:$C$666=$C5)*(ISNUMBER(MATCH(Data!$D$2:$D$666,CurrentMonths,0)))*Data!$E$2:$E$666) -> -88890.38 | F5: =E5-D5 -> -374281.24 | G5: =IF(D5=0,"",F5/ABS(D5)) -> -1.3114689 | H5: =IF(ABS(F5)>=Threshold,"Yes","No") -> Yes | I5: United States / AMER / NY7
A6: Singapore | B6: APAC | C6: SG4 | D6: =SUMPRODUCT((Data!$A$2:$A$666=$A6)*(Data!$B$2:$B$666=$B6)*(Data!$C$2:$C$666=$C6)*(ISNUMBER(MATCH(Data!$D$2:$D$666,BaseMonths,0)))*Data!$E$2:$E$666) -> 144966.12 | E6: =SUMPRODUCT((Data!$A$2:$A$666=$A6)*(Data!$B$2:$B$666=$B6)*(Data!$C$2:$C$666=$C6)*(ISNUMBER(MATCH(Data!$D$2:$D$666,CurrentMonths,0)))*Data!$E$2:$E$666) -> 448730.36 | F6: =E6-D6 -> 303764.24 | G6: =IF(D6=0,"",F6/ABS(D6)) -> 2.0954154 | H6: =IF(ABS(F6)>=Threshold,"Yes","No") -> Yes | I6: Singapore / APAC / SG4
A7: Hong Kong | B7: APAC | C7: HK2 | D7: =SUMPRODUCT((Data!$A$2:$A$666=$A7)*(Data!$B$2:$B$666=$B7)*(Data!$C$2:$C$666=$C7)*(ISNUMBER(MATCH(Data!$D$2:$D$666,BaseMonths,0)))*Data!$E$2:$E$666) -> 341809.39 | E7: =SUMPRODUCT((Data!$A$2:$A$666=$A7)*(Data!$B$2:$B$666=$B7)*(Data!$C$2:$C$666=$C7)*(ISNUMBER(MATCH(Data!$D$2:$D$666,CurrentMonths,0)))*Data!$E$2:$E$666) -> 633756.63 | F7: =E7-D7 -> 291947.24 | G7: =IF(D7=0,"",F7/ABS(D7)) -> 0.85412294 | H7: =IF(ABS(F7)>=Threshold,"Yes","No") -> No | I7: Other items
A8: United States | B8: AMER | C8: NY13 | D8: =SUMPRODUCT((Data!$A$2:$A$666=$A8)*(Data!$B$2:$B$666=$B8)*(Data!$C$2:$C$666=$C8)*(ISNUMBER(MATCH(Data!$D$2:$D$666,BaseMonths,0)))*Data!$E$2:$E$666) -> 176444.83 | E8: =SUMPRODUCT((Data!$A$2:$A$666=$A8)*(Data!$B$2:$B$666=$B8)*(Data!$C$2:$C$666=$C8)*(ISNUMBER(MATCH(Data!$D$2:$D$666,CurrentMonths,0)))*Data!$E$2:$E$666) -> -104711.23 | F8: =E8-D8 -> -281156.06 | G8: =IF(D8=0,"",F8/ABS(D8)) -> -1.5934503 | H8: =IF(ABS(F8)>=Threshold,"Yes","No") -> No | I8: Other items
A9: United Kingdom | B9: EMEA | C9: LD6 | D9: =SUMPRODUCT((Data!$A$2:$A$666=$A9)*(Data!$B$2:$B$666=$B9)*(Data!$C$2:$C$666=$C9)*(ISNUMBER(MATCH(Data!$D$2:$D$666,BaseMonths,0)))*Data!$E$2:$E$666) -> 497242.02 | E9: =SUMPRODUCT((Data!$A$2:$A$666=$A9)*(Data!$B$2:$B$666=$B9)*(Data!$C$2:$C$666=$C9)*(ISNUMBER(MATCH(Data!$D$2:$D$666,CurrentMonths,0)))*Data!$E$2:$E$666) -> 220730.16 | F9: =E9-D9 -> -276511.86 | G9: =IF(D9=0,"",F9/ABS(D9)) -> -0.5560911 | H9: =IF(ABS(F9)>=Threshold,"Yes","No") -> No | I9: Other items
A10: United States | B10: AMER | C10: NY9 | D10: =SUMPRODUCT((Data!$A$2:$A$666=$A10)*(Data!$B$2:$B$666=$B10)*(Data!$C$2:$C$666=$C10)*(ISNUMBER(MATCH(Data!$D$2:$D$666,BaseMonths,0)))*Data!$E$2:$E$666) -> 167358.02 | E10: =SUMPRODUCT((Data!$A$2:$A$666=$A10)*(Data!$B$2:$B$666=$B10)*(Data!$C$2:$C$666=$C10)*(ISNUMBER(MATCH(Data!$D$2:$D$666,CurrentMonths,0)))*Data!$E$2:$E$666) -> -103477.24 | F10: =E10-D10 -> -270835.26 | G10: =IF(D10=0,"",F10/ABS(D10)) -> -1.6182987 | H10: =IF(ABS(F10)>=Threshold,"Yes","No") -> No | I10: Other items
A11: Germany | B11: EMEA | C11: FR5 | D11: =SUMPRODUCT((Data!$A$2:$A$666=$A11)*(Data!$B$2:$B$666=$B11)*(Data!$C$2:$C$666=$C11)*(ISNUMBER(MATCH(Data!$D$2:$D$666,BaseMonths,0)))*Data!$E$2:$E$666) -> 277039.09 | E11: =SUMPRODUCT((Data!$A$2:$A$666=$A11)*(Data!$B$2:$B$666=$B11)*(Data!$C$2:$C$666=$C11)*(ISNUMBER(MATCH(Data!$D$2:$D$666,CurrentMonths,0)))*Data!$E$2:$E$666) -> 29848.07 | F11: =E11-D11 -> -247191.02 | G11: =IF(D11=0,"",F11/ABS(D11)) -> -0.89226044 | H11: =IF(ABS(F11)>=Threshold,"Yes","No") -> No | I11: Other items
A12: United Kingdom | B12: EMEA | C12: LD4 | D12: =SUMPRODUCT((Data!$A$2:$A$666=$A12)*(Data!$B$2:$B$666=$B12)*(Data!$C$2:$C$666=$C12)*(ISNUMBER(MATCH(Data!$D$2:$D$666,BaseMonths,0)))*Data!$E$2:$E$666) -> 318550.22 | E12: =SUMPRODUCT((Data!$A$2:$A$666=$A12)*(Data!$B$2:$B$666=$B12)*(Data!$C$2:$C$666=$C12)*(ISNUMBER(MATCH(Data!$D$2:$D$666,CurrentMonths,0)))*Data!$E$2:$E$666) -> 85507.34 | F12: =E12-D12 -> -233042.88 | G12: =IF(D12=0,"",F12/ABS(D12)) -> -0.73157344 | H12: =IF(ABS(F12)>=Threshold,"Yes","No") -> No | I12: Other items
A13: Italy | B13: EMEA | C13: ML5 | D13: =SUMPRODUCT((Data!$A$2:$A$666=$A13)*(Data!$B$2:$B$666=$B13)*(Data!$C$2:$C$666=$C13)*(ISNUMBER(MATCH(Data!$D$2:$D$666,BaseMonths,0)))*Data!$E$2:$E$666) -> 272403.45 | E13: =SUMPRODUCT((Data!$A$2:$A$666=$A13)*(Data!$B$2:$B$666=$B13)*(Data!$C$2:$C$666=$C13)*(ISNUMBER(MATCH(Data!$D$2:$D$666,CurrentMonths,0)))*Data!$E$2:$E$666) -> 48962.98 | F13: =E13-D13 -> -223440.47 | G13: =IF(D13=0,"",F13/ABS(D13)) -> -0.82025565 | H13: =IF(ABS(F13)>=Threshold,"Yes","No") -> No | I13: Other items
... A340: United States | B340: AMER | C340: ARQUES OFFICE | D340: =SUMPRODUCT((Data!$A$2:$A$666=$A340)*(Data!$B$2:$B$666=$B340)*(Data!$C$2:$C$666=$C340)*(ISNUMBER(MATCH(Data!$D$2:$D$666,BaseMonths,0)))*Data!$E$2:$E$666) -> 260673.5 | E340: =SUMPRODUCT((Data!$A$2:$A$666=$A340)*(Data!$B$2:$B$666=$B340)*(Data!$C$2:$C$666=$C340)*(ISNUMBER(MATCH(Data!$D$2:$D$666,CurrentMonths,0)))*Data!$E$2:$E$666) -> 260673.5 | F340: =E340-D340 -> 0 | G340: =IF(D340=0,"",F340/ABS(D340)) -> 0 | H340: =IF(ABS(F340)>=Threshold,"Yes","No") -> No | I340: Other items

Sheet Data checks
A1: Check | B1: Engine value | C1: Workbook value | D1: Difference | E1: Result
A2: Base total | B2: 27160793 | C2: =TotalBase -> 27160793 | D2: =C2-B2 -> 0 | E2: =IF(ABS(D2)<0.005,"OK","Check") -> OK
A3: Current total | B3: 21173166 | C3: =TotalCurrent -> 21173166 | D3: =C3-B3 -> 0 | E3: =IF(ABS(D3)<0.005,"OK","Check") -> OK
A4: Movement lines add up to the total movement | B4: -5987626.9 | C4: =SUM(Commentary!$G$2:$G$7) -> -5987626.9 | D4: =C4-B4 -> -9.3132257e-10 | E4: =IF(ABS(D4)<0.005,"OK","Check") -> OK
A5: Drill-down lines add up to the total movement | B5: -5987626.9 | C5: =SUM('Drill-down'!$F$2:$F$340) -> -5987626.9 | D5: =C5-B5 -> 0 | E5: =IF(ABS(D5)<0.005,"OK","Check") -> OK
A7: Data controls run before the report
A8: required_columns | B8: Passed | C8: All required columns are available.
A9: periods_present | B9: Passed | C9: Both comparison slices contain data.
A10: no_duplicate_periods_across_files | B10: Passed | C10: No periods overlap across stacked sources.
A11: new_or_removed_members | B11: Warning | C11: New or removed dimension members were found; see details.
A12: join_unmatched_keys | B12: Passed | C12: All lookup keys matched.
A13: join_fanout | B13: Passed | C13: Lookup joins preserve one row per source row.
A14: classification_coverage | B14: Passed | C14: Classification coverage meets the configured minimum.
A15: partial_period_used | B15: Passed | C15: No detected partial months are selected.
A16: drivers_reconcile | B16: Passed | C16: Drivers and other items reconcile to the movement.
A17: flags_sum_to_rows | B17: Passed | C17: Flag counts reconcile to view rows.
A18: sections_reconcile | B18: Passed | C18: No section split configured.
A20: Full details are on the Data controls sheet.

Sheet Data
A1: Country | B1: Region | C1: Ibx_Code | D1: Month | E1: Amount
A2: Australia | B2: APAC | C2: AE1 | D2: 2026-06 | E2: 17203.27
A3: Australia | B3: APAC | C3: AE1 | D3: 2026-07 | E3: 2712.05
A4: Australia | B4: APAC | C4: BR1 | D4: 2026-06 | E4: 10829.63
A5: Australia | B5: APAC | C5: BR1 | D5: 2026-07 | E5: 7752
A6: Australia | B6: APAC | C6: CA1 | D6: 2026-06 | E6: 46074.06
A7: Australia | B7: APAC | C7: CA1 | D7: 2026-07 | E7: 13900.67
A8: Australia | B8: APAC | C8: ME1 | D8: 2026-06 | E8: 46448.88
A9: Australia | B9: APAC | C9: ME1 | D9: 2026-07 | E9: 78530.53
A10: Australia | B10: APAC | C10: ME2 | D10: 2026-06 | E10: 22980.71
A11: Australia | B11: APAC | C11: ME2 | D11: 2026-07 | E11: 53974.01
A12: Australia | B12: APAC | C12: ME4 | D12: 2026-06 | E12: 41692.75
A13: Australia | B13: APAC | C13: ME4 | D13: 2026-07 | E13: 142908.55
... A666: United States | B666: AMER | C666: TAMPA OFFICE | D666: 2026-07 | E666: 1537.81

Sheet Settings
A1: Report settings
A3: Report | B3: Untitled analysis
A4: Run ID | B4: 2d9ad6a79f424c46a40c41620856df90
A5: Created (UTC) | B5: 46323.6
A6: Comparison | B6: period_vs_period
A7: Base months | B7: 2026-06
A8: Current months | B8: 2026-07
A9: Base version | B9: All versions
A10: Current version | B10: All versions
A11: Threshold | B11: 300000
A12: Movements shown (top N) | B12: 15
A13: Remaining movements label | B13: Other items
A14: Currency | B14: $
A15: How amounts are calculated | B15: Formulas over the Data sheet
A16: Why | B16: Every line was checked against the engine before saving.
A17: Setup fingerprint (SHA-256) | B17: 0964d7c5009905b14343263bfc4d4611cc49866d5ca11585bbf44538e7815f90
A19: Change Threshold to see which movements cross it. The list of movements was chosen when the report ran; run the report again to change months, versions or the list.

Sheet Variance - By country
A1: Country | B1: Region | C1: Ibx Code | D1: Base | E1: Current | F1: Change | G1: Change %
A2: Brazil | B2: AMER | C2: SP3 | D2: 440441.66 | E2: -2367.7 | F2: -442809.36 | G2: -1.0053757
A3: Brazil | B3: AMER | C3: SP4 | D3: 121381.14 | E3: 212374.16 | F3: 90993.02 | G3: 0.7496471
A4: Canada | B4: AMER | C4: MT97 | D4: 17470.3 | E4: 21581.67 | F4: 4111.37 | G4: 0.23533483
A5: Germany | B5: EMEA | C5: FR1 | D5: 67153.39 | E5: 89043.31 | F5: 21889.92 | G5: 0.32596895
A6: Germany | B6: EMEA | C6: FR2 | D6: 1128962 | E6: 704639.62 | F6: -424322.34 | G6: -0.37585176
A7: Finland | B7: EMEA | C7: HE6 | D7: 143616.32 | E7: 43546.34 | F7: -100069.98 | G7: -0.69678697
A8: Finland | B8: EMEA | C8: HE7 | D8: 117591.99 | E8: 40958.7 | F8: -76633.29 | G8: -0.65168801
A9: Korea | B9: APAC | C9: SL1 | D9: 10786.46 | E9: 13663.64 | F9: 2877.18 | G9: 0.26673997
A10: Mauritius | B10: EMEA | C10: MAURITIUS (MAINONE) | D10: 178532.95 | E10: 42450.5 | F10: -136082.45 | G10: -0.76222596
A11: Netherlands | B11: EMEA | C11: AM6 | D11: 105077.7 | E11: 46903.31 | F11: -58174.39 | G11: -0.55363212
A12: Poland | B12: EMEA | C12: WA3 | D12: 99782.05 | E12: 38034.41 | F12: -61747.64 | G12: -0.61882513
A13: Portugal | B13: EMEA | C13: PORTUGAL OFFICE (MAINONE) | D13: 2220.71 | E13: 5575.21 | F13: 3354.5 | G13: 1.5105529
... A17: United States | B17: AMER | C17: MI6 | D17: 91885 | E17: 49136.16 | F17: -42748.84 | G17: -0.46524286
A18: United States | B18: AMER | C18: CHICAGO OFFICE | D18: 0 | E18: -140.07 | F18: -140.07
A19: United States | B19: AMER | C19: SV18 | D19: 6329.2 | E19: 16726.61 | F19: 10397.41 | G19: 1.6427684
A20: United States | B20: AMER | C20: SV3 | D20: 246972.51 | E20: 90467.51 | F20: -156505 | G20: -0.63369401
A21: United States | B21: AMER | C21: GLOBAL HQ | D21: 774045.08 | E21: 695924.93 | F21: -78120.15 | G21: -0.10092455
A22: United States | B22: AMER | C22: NY7 | D22: 285390.86 | E22: -88890.38 | F22: -374281.24 | G22: -1.3114689
A23: United States | B23: AMER | C23: NY13 | D23: 176444.83 | E23: -104711.23 | F23: -281156.06 | G23: -1.5934503
A24: United States | B24: AMER | C24: NY9 | D24: 167358.02 | E24: -103477.24 | F24: -270835.26 | G24: -1.6182987
A25: Malaysia | B25: APAC | C25: JH2 | D25: 6315.62 | E25: 980.81 | F25: -5334.81 | G25: -0.84470092
A26: United States | B26: AMER | C26: SV20 SILICON VALLEY | D26: 41551.97 | E26: 41424.61 | F26: -127.36 | G26: -0.0030650773
A27: United Arab Emirates | B27: EMEA | C27: AD1 | D27: 2922.88 | E27: 2317.7 | F27: -605.18 | G27: -0.20704921
A28: United Arab Emirates | B28: EMEA | C28: DX1 | D28: 73223.01 | E28: 86567.6 | F28: 13344.59 | G28: 0.18224585
A29: United Arab Emirates | B29: EMEA | C29: DX3 | D29: 58549.42 | E29: 23971.62 | F29: -34577.8 | G29: -0.59057459
A30: United Arab Emirates | B30: EMEA | C30: DX2 | D30: 207.3 | E30: 207.3 | F30: 0 | G30: 0
... A78: Chile | B78: AMER | C78: ST4 | D78: 23859.26 | E78: 16232.68 | F78: -7626.58 | G78: -0.31964864
A79: Chile | B79: AMER | C79: SANTIAGO OFFICE | D79: 0 | E79: 1048.43 | F79: 1048.43
A80: China | B80: APAC | C80: SH5 | D80: 123895.8 | E80: 53975.22 | F80: -69920.58 | G80: -0.56434988
A81: China | B81: APAC | C81: SH2 | D81: 62730.8 | E81: 12726.34 | F81: -50004.46 | G81: -0.79712773
A82: China | B82: APAC | C82: SH3 | D82: 39314.86 | E82: 54037.85 | F82: 14722.99 | G82: 0.37448919
A83: China | B83: APAC | C83: SHANGHAI OFFICE | D83: 9015.74 | E83: 736.62 | F83: -8279.12 | G83: -0.91829622
A84: China | B84: APAC | C84: SH6 | D84: 104534.12 | E84: 224440.22 | F84: 119906.1 | G84: 1.1470523
A85: Colombia | B85: AMER | C85: BG1 | D85: 52392.52 | E85: 32982.47 | F85: -19410.05 | G85: -0.37047369
A86: Colombia | B86: AMER | C86: BG2 | D86: 86618.91 | E86: 16705.63 | F86: -69913.28 | G86: -0.80713646
A87: Colombia | B87: AMER | C87: BOGOTA OFFICE BGS | D87: 300.38 | E87: 935.19 | F87: 634.81 | G87: 2.1133564
A88: Germany | B88: EMEA | C88: FRANKFURT (FRN) OFFICE | D88: 21277.08 | E88: 72319.32 | F88: 51042.24 | G88: 2.3989307
A89: Germany | B89: EMEA | C89: FR7 | D89: 233632.69 | E89: 231084.75 | F89: -2547.94 | G89: -0.010905751
A90: Germany | B90: EMEA | C90: FR4 | D90: 243678.81 | E90: 328291.76 | F90: 84612.95 | G90: 0.34723146
...

Sheet Movement detail
A1: Movement | B1: Country | C1: Region | D1: Ibx Code | E1: Base | F1: Current | G1: Change | H1: Change % | I1: Lines | J1: Flags | K1: Top descriptions | L1: Evidence references | M1: Movement ID
A2: Brazil / AMER / SP3 | B2: Brazil | C2: AMER | D2: SP3 | E2: 440441.66 | F2: -2367.7 | G2: -442809.36 | H2: -1.0053757 | I2: 513 | K2: GAO6111_AP_0626_AMER Manual Acc_A5-NoXZSEfGJGSVu_9IVgQ-300000131614726-ACCR-100002823917343 , VERTIV TECNOLOGIA DO BRASIL LTDA|R&M , 8002 , 14429487 (-$0.1M); GAO6111_AP_0626_AMER Manual Acc_A5-NoXZSEfGJGSVu_9IVgQ-300000131614726-ACCR-100002823917343 , VERTIV TECNOLOGIA DO BRASIL LTDA|R&M , 8002 , 14429488 (-$0.1M); GAO5203_MD_0626_OpenPOCath_lnw3d3VcEfGJGSVu_9IVgQ-300000131614726-ACCR-100002819269393 , 1110592271-1_VERTIV TECNOLOGIA DO BRASIL LTDA_SP3 Vertiv as per amendm (-$0.1M); GAO5203_MD_0626_OpenPOCath_lnw3d3VcEfGJGSVu_9IVgQ-300000131614726-ACCR-100002819269393 , 1110592271-1_VERTIV TECNOLOGIA DO BRASIL LTDA_SP3 Vertiv as per amendm (-$0.1M); PO Number: 1110572259 , PO Line Number: 1 ,Supplier Name: CUMMINS VENDAS E SERVICOS DE MOTORES E GERADORES LTDA Invoice Number: 343422-4-20260521-61838884000142 (-$36,053.72) | L2: driver:d1 | M2: d1
A3: Germany / EMEA / FR2 | B3: Germany | C3: EMEA | D3: FR2 | E3: 1128962 | F3: 704639.62 | G3: -424322.34 | H3: -0.37585176 | I3: 1083 | K3: GAO5049_KB_0526_OpenPO WW_VHUHT1qnEfGpxZVkiKiA2g-300000131614726-ACCR-100002737255229 , 1590535725-2_ACTEMIUM CEGELEC GMBH_FR2.1-6 2026 Q2 maintenance of fire m (+$0.1M); PO Number: 1590535725 , PO Line Number: 2 ,Supplier Name: ACTEMIUM CEGELEC GMBH Invoice Number: 1870021642 Description: FR2.1-6 2026 Q2 maintenance of fire moni (-$0.1M); GAO5049_KB_0526_OpenPO WW_VHUHT1qnEfGpxZVkiKiA2g-300000131614726-ACCR-100002737255229 , 1590566063-1_SOCOMEC GMBH_FR2 Impedance measurement Semi Annual Maintena (+$0.1M); PO Number: 1590566063 , PO Line Number: 1 ,Supplier Name: SOCOMEC GMBH Invoice Number: 800 / 31256535 Description: FR2 Impedance measurement Semi Annual Mainten (-$0.1M); GAO5049_KB_0626_OpenPO WW_5MUniXOlEfGxWZ1NRsFAkA-300000131614726-ACCR-100002808784117 , 1590548361-1_HEINRICH BOLLMANN GMBH_FR2 - 2026 Sachkundigenprfung und Wa (-$0.1M) | L3: driver:d2 | M3: d2
A4: United States / AMER / DC12 | B4: United States | C4: AMER | D4: DC12 | E4: 716637.09 | F4: 321587.31 | G4: -395049.78 | H4: -0.551255 | I4: 268 | K4: GAO5049_KB_0626_OpenPO WW_5MUniXOlEfGxWZ1NRsFAkA-300000131614726-ACCR-100002809437203 , 1040590899-1_EBM PAPST INC US CT FARMI IV 456_DC12-EBMPAPST as per quote (-$0.2M); GAO5049_KB_0626_OpenPO WW_5MUniXOlEfGxWZ1NRsFAkA-300000131614726-ACCR-100002809437203 , 1040590899-1_EBM PAPST INC US CT FARMI IV 456_DC12-EBMPAPST as per quote (-$0.2M); GAO5049_KB_0726_OpenPO WW_M3Z9-4xYEfGhDpMHE24o3Q-300000131614726-ACCR-100002877409113 , 1040590899-1_EBM PAPST INC US CT FARMI IV 456_DC12-EBMPAPST as per quote (+$0.2M); GAO5049_KB_0526_OpenPO WW_VHUHT1qnEfGpxZVkiKiA2g-300000131614726-ACCR-100002737453098 , 1040543939-1_EBM PAPST INC US CT FARMI IV 456_DC12: Supply Fan Part #R3G (+$0.2M); GAO5049_KB_0626_OpenPO WW_5MUniXOlEfGxWZ1NRsFAkA-300000131614726-ACCR-100002809437203 , 1040543939-1_EBM PAPST INC US CT FARMI IV 456_DC12: Supply Fan Part #R3G (-$0.2M) | L4: driver:d3 | M4: d3
A5: United States / AMER / NY7 | B5: United States | C5: AMER | D5: NY7 | E5: 285390.86 | F5: -88890.38 | G5: -374281.24 | H5: -1.3114689 | I5: 284 | K5: PO Number: 1040573824 , PO Line Number: 2 ,Supplier Name: CARRIER CORPORATION Invoice Number: 90543992 Description: NY7: Labor per Carrier quote dated 04/06/202 (-$29,362.39); PO Number: 1040566040 , PO Line Number: 2 ,Supplier Name: ORR PROTECTION SYSTEMS INC Invoice Number: IN-0086444 Description: NY7: Q2 2026 - Orr Fire protection (+$22,124.69); GAO5049_KB_0526_OpenPO WW_VHUHT1qnEfGpxZVkiKiA2g-300000131614726-ACCR-100002737453098 , 1040457223-1_NALCO COMPANY FKA ONDEO NALCO COMPANY_NY7 $41032.14-BPO Che (+$19,142.64); GAO5049_KB_0626_OpenPO WW_5MUniXOlEfGxWZ1NRsFAkA-300000131614726-ACCR-100002809437203 , 1040457223-1_NALCO COMPANY FKA ONDEO NALCO COMPANY_NY7 $41032.14-BPO Che (-$19,142.64) | L5: driver:d4 | M5: d4
A6: Singapore / APAC / SG4 | B6: Singapore | C6: APAC | D6: SG4 | E6: 144966.12 | F6: 448730.36 | G6: 303764.24 | H6: 2.0954154 | I6: 603 | K6: PO Number: 1400559725 , PO Line Number: 1 ,Supplier Name: EATON ELECTRIC SINGAPORE PTE LTD Invoice Number: 957921169 Description: UPS Model: Eaton 9395P-1200kVA (+$0.1M); GAO5153_NS_0726_OpePO APACRe_K1IRko2YEfGhDpMHE24o3Q-300000131614726-ACCR-100002883223886 , 1400585681-1_ROCKWELL AUTOMATION SOUTHEAST ASIA PTE LIMITED_SG4 CPOS (+$0.1M); PO Number: 1400583089 , PO Line Number: 1 ,Supplier Name: LC ENGINEERING SERVICES PTE LTD Invoice Number: 26/J-1333/I-29468 Description: SG4 Level 1/2/3/4/5/7. (+$0.1M); GAO5153_NS_0726_OpePO APACRe_K1IRko2YEfGhDpMHE24o3Q-300000131614726-ACCR-100002883223886 , 1400559720-1_EATON ELECTRIC SINGAPORE PTE LTD_SN1 Non Comprehensive M (+$38,693.52); GAO5153_NS_0626_OpePO APACRe_xG9IjHShEfGxWZ1NRsFAkA-300000131614726-ACCR-100002813198521 , 1400559720-1_EATON ELECTRIC SINGAPORE PTE LTD_SN1 Non Comprehensive M (-$33,623.26) | L6: driver:d5 | M6: d5
A7: Other items | E7: 24444396 | F7: 19789467 | G7: -4654928.5 | H7: -0.19042927 | I7: 55784 | K7: GAO5049_KB_0526_OpenPO WW_VHUHT1qnEfGpxZVkiKiA2g-300000131614726-ACCR-100002737453098 , 1040525989-2_TAMPA ARMATURE WORKS INC DBA INTEGRATED POWER SERVICES_MI6 (+$0.2M); GAO5049_KB_0626_OpenPO WW_5MUniXOlEfGxWZ1NRsFAkA-300000131614726-ACCR-100002809437203 , 1040525989-2_TAMPA ARMATURE WORKS INC DBA INTEGRATED POWER SERVICES_MI6 (-$0.2M); GAO5049_KB_0626_OpenPO WW_5MUniXOlEfGxWZ1NRsFAkA-300000131614726-ACCR-100002809437203 , 1040525989-2_TAMPA ARMATURE WORKS INC DBA INTEGRATED POWER SERVICES_MI6 (-$0.2M); GAO5049_KB_0726_OpenPO WW_M3Z9-4xYEfGhDpMHE24o3Q-300000131614726-ACCR-100002877409113 , 1040525989-2_TAMPA ARMATURE WORKS INC DBA INTEGRATED POWER SERVICES_MI6 (+$0.2M) | L7: driver:others | M7: others

Sheet Source lines
A1: Movement | B1: Description | C1: Base | D1: Current | E1: Change | F1: Lines | G1: Movement ID
A2: Brazil / AMER / SP3 | B2: GAO6111_AP_0626_AMER Manual Acc_A5-NoXZSEfGJGSVu_9IVgQ-300000131614726-ACCR-100002823917343 , VERTIV TECNOLOGIA DO BRASIL LTDA|R&M , 8002 , 14429487 | C2: 127237.05 | D2: 0 | E2: -127237.05 | F2: 1 | G2: d1
A3: Brazil / AMER / SP3 | B3: GAO6111_AP_0626_AMER Manual Acc_A5-NoXZSEfGJGSVu_9IVgQ-300000131614726-ACCR-100002823917343 , VERTIV TECNOLOGIA DO BRASIL LTDA|R&M , 8002 , 14429488 | C3: 0 | D3: -127237.05 | E3: -127237.05 | F3: 1 | G3: d1
A4: Brazil / AMER / SP3 | B4: GAO5203_MD_0626_OpenPOCath_lnw3d3VcEfGJGSVu_9IVgQ-300000131614726-ACCR-100002819269393 , 1110592271-1_VERTIV TECNOLOGIA DO BRASIL LTDA_SP3 Vertiv as per amendment No. 2 TO Monthly contract for preventive thermal maintenance on Vertiv equipments. Replacing PO 1110468527. January/26 to December/26 , 8002 , 14388964 | C4: 125800.91 | D4: 0 | E4: -125800.91 | F4: 1 | G4: d1
A5: Brazil / AMER / SP3 | B5: GAO5203_MD_0626_OpenPOCath_lnw3d3VcEfGJGSVu_9IVgQ-300000131614726-ACCR-100002819269393 , 1110592271-1_VERTIV TECNOLOGIA DO BRASIL LTDA_SP3 Vertiv as per amendment No. 2 TO Monthly contract for preventive thermal maintenance on Vertiv equipments. Replacing PO 1110468527. January/26 to December/26 , 8002 , 14388965 | C5: 0 | D5: -125800.91 | E5: -125800.91 | F5: 1 | G5: d1
A6: Brazil / AMER / SP3 | B6: PO Number: 1110572259 , PO Line Number: 1 ,Supplier Name: CUMMINS VENDAS E SERVICOS DE MOTORES E GERADORES LTDA Invoice Number: 343422-4-20260521-61838884000142 Description: SP3, CUMMINS quote 274686, dated in 1/26/26 - Purchase material BATERIA 34R REDTOP 12V-50AH-3 | C6: 36053.72 | D6: 0 | E6: -36053.72 | F6: 6 | G6: d1
A7: Brazil / AMER / SP3 | B7: Remaining transactions | C7: 151349.98 | D7: 250670.26 | E7: 99320.28 | F7: 503 | G7: d1
A8: Germany / EMEA / FR2 | B8: GAO5049_KB_0526_OpenPO WW_VHUHT1qnEfGpxZVkiKiA2g-300000131614726-ACCR-100002737255229 , 1590535725-2_ACTEMIUM CEGELEC GMBH_FR2.1-6 2026 Q2 maintenance of fire monitoring and protection system , 8002 , 13579867 | C8: -126684 | D8: 0 | E8: 126684 | F8: 1 | G8: d2
A9: Germany / EMEA / FR2 | B9: PO Number: 1590535725 , PO Line Number: 2 ,Supplier Name: ACTEMIUM CEGELEC GMBH Invoice Number: 1870021642 Description: FR2.1-6 2026 Q2 maintenance of fire monitoring and protection system | C9: 125982 | D9: 0 | E9: -125982 | F9: 1 | G9: d2
A10: Germany / EMEA / FR2 | B10: GAO5049_KB_0526_OpenPO WW_VHUHT1qnEfGpxZVkiKiA2g-300000131614726-ACCR-100002737255229 , 1590566063-1_SOCOMEC GMBH_FR2 Impedance measurement Semi Annual Maintenance April , 8002 , 13580399 | C10: -108502.5 | D10: 0 | E10: 108502.5 | F10: 1 | G10: d2
A11: Germany / EMEA / FR2 | B11: PO Number: 1590566063 , PO Line Number: 1 ,Supplier Name: SOCOMEC GMBH Invoice Number: 800 / 31256535 Description: FR2 Impedance measurement Semi Annual Maintenance April | C11: 107901.25 | D11: 0 | E11: -107901.25 | F11: 1 | G11: d2
A12: Germany / EMEA / FR2 | B12: GAO5049_KB_0626_OpenPO WW_5MUniXOlEfGxWZ1NRsFAkA-300000131614726-ACCR-100002808784117 , 1590548361-1_HEINRICH BOLLMANN GMBH_FR2 - 2026 Sachkundigenprfung und Wartung fr Brandschutztren und Feststellanlagen , 8002 , 14329004 | C12: 90267.09 | D12: 0 | E12: -90267.09 | F12: 1 | G12: d2
A13: Germany / EMEA / FR2 | B13: Remaining transactions | C13: 1039998.1 | D13: 704639.62 | E13: -335358.5 | F13: 1078 | G13: d2
... A19: United States / AMER / DC12 | B19: Remaining transactions | C19: 492637.09 | D19: 321587.31 | E19: -171049.78 | F19: 263 | G19: d3
A20: United States / AMER / NY7 | C20: 140000 | D20: -140000 | E20: -280000 | F20: 2 | G20: d4
A21: United States / AMER / NY7 | B21: PO Number: 1040573824 , PO Line Number: 2 ,Supplier Name: CARRIER CORPORATION Invoice Number: 90543992 Description: NY7: Labor per Carrier quote dated 04/06/2026 | C21: 29362.39 | D21: 0 | E21: -29362.39 | F21: 2 | G21: d4
A22: United States / AMER / NY7 | B22: PO Number: 1040566040 , PO Line Number: 2 ,Supplier Name: ORR PROTECTION SYSTEMS INC Invoice Number: IN-0086444 Description: NY7: Q2 2026 - Orr Fire protection to provide annual inspection per proposal dated 1/1/2026. This PR replaces PO 1040458821. Billed Quarterly (Mar, Jun, Sep and Dec) | C22: 0 | D22: 22124.69 | E22: 22124.69 | F22: 2 | G22: d4
A23: United States / AMER / NY7 | B23: GAO5049_KB_0526_OpenPO WW_VHUHT1qnEfGpxZVkiKiA2g-300000131614726-ACCR-100002737453098 , 1040457223-1_NALCO COMPANY FKA ONDEO NALCO COMPANY_NY7 $41032.14-BPO Chemicals Only - Nalco per Agreement No. 00064991.0 effective date November 30th 2022. Vendor will provide chemicals to treat chilled water system and ensure the sy , 8001 , 13588824 | C23: -19142.64 | D23: 0 | E23: 19142.64 | F23: 1 | G23: d4
A24: United States / AMER / NY7 | B24: GAO5049_KB_0626_OpenPO WW_5MUniXOlEfGxWZ1NRsFAkA-300000131614726-ACCR-100002809437203 , 1040457223-1_NALCO COMPANY FKA ONDEO NALCO COMPANY_NY7 $41032.14-BPO Chemicals Only - Nalco per Agreement No. 00064991.0 effective date November 30th 2022. Vendor will provide chemicals to treat chilled water system and ensure the sy , 8001 , 14352254 | C24: 19142.64 | D24: 0 | E24: -19142.64 | F24: 1 | G24: d4
A25: United States / AMER / NY7 | B25: Remaining transactions | C25: 116028.47 | D25: 28984.93 | E25: -87043.54 | F25: 276 | G25: d4
A26: Singapore / APAC / SG4 | B26: PO Number: 1400559725 , PO Line Number: 1 ,Supplier Name: EATON ELECTRIC SINGAPORE PTE LTD Invoice Number: 957921169 Description: UPS Model: Eaton 9395P-1200kVA | C26: 0 | D26: 92750.04 | E26: 92750.04 | F26: 5 | G26: d5
A27: Singapore / APAC / SG4 | B27: GAO5153_NS_0726_OpePO APACRe_K1IRko2YEfGhDpMHE24o3Q-300000131614726-ACCR-100002883223886 , 1400585681-1_ROCKWELL AUTOMATION SOUTHEAST ASIA PTE LIMITED_SG4 CPOS SCADA Standardization Solution per Quotation 30605123.2 , 8000 , 15172381 | C27: 0 | D27: 71471.63 | E27: 71471.63 | F27: 1 | G27: d5
A28: Singapore / APAC / SG4 | B28: PO Number: 1400583089 , PO Line Number: 1 ,Supplier Name: LC ENGINEERING SERVICES PTE LTD Invoice Number: 26/J-1333/I-29468 Description: SG4 Level 1/2/3/4/5/7. Supply expertise and equipment to perform Thermal Scanning for the follow LV Equipment: a) GSM LV Switchboard 210 nos b) Data Hall busducts 69 nos c) Base built LV Switchboard 4 nos d) Test Report Endorsement & Report | C28: 0 | D28: 51630.85 | E28: 51630.85 | F28: 1 | G28: d5
A29: Singapore / APAC / SG4 | B29: GAO5153_NS_0726_OpePO APACRe_K1IRko2YEfGhDpMHE24o3Q-300000131614726-ACCR-100002883223886 , 1400559720-1_EATON ELECTRIC SINGAPORE PTE LTD_SN1 Non Comprehensive Maintenance w 1 x Shutdown PM (In Hours Rates) Contract Period 12 Months (1 Jan 2026 to 31 Dec 2026)UPS Model :Eaton 9395P 1200kVA , 8002 , 15172499 | C29: 0 | D29: 38693.52 | E29: 38693.52 | F29: 1 | G29: d5
A30: Singapore / APAC / SG4 | B30: GAO5153_NS_0626_OpePO APACRe_xG9IjHShEfGxWZ1NRsFAkA-300000131614726-ACCR-100002813198521 , 1400559720-1_EATON ELECTRIC SINGAPORE PTE LTD_SN1 Non Comprehensive Maintenance w 1 x Shutdown PM (In Hours Rates) Contract Period 12 Months (1 Jan 2026 to 31 Dec 2026)UPS Model Eaton 9395P 1200kVA , 8002 , 14377026 | C30: 33623.26 | D30: 0 | E30: -33623.26 | F30: 1 | G30: d5
A31: Singapore / APAC / SG4 | B31: Remaining transactions | C31: 111342.86 | D31: 194184.32 | E31: 82841.46 | F31: 594 | G31: d5
A32: Other items | C32: 401629.54 | D32: 109986.61 | E32: -291642.93 | F32: 2198 | G32: others
A33: Other items | B33: GAO5049_KB_0526_OpenPO WW_VHUHT1qnEfGpxZVkiKiA2g-300000131614726-ACCR-100002737453098 , 1040525989-2_TAMPA ARMATURE WORKS INC DBA INTEGRATED POWER SERVICES_MI6 IPS as per quote 50030589-4 dated 10.30.25 for repairs needed on Generator 1A - SN: H000135346. Labor. , 8000 , 13588778 | C33: -220232.05 | D33: 0 | E33: 220232.05 | F33: 1 | G33: others
A34: Other items | B34: GAO5049_KB_0626_OpenPO WW_5MUniXOlEfGxWZ1NRsFAkA-300000131614726-ACCR-100002809437203 , 1040525989-2_TAMPA ARMATURE WORKS INC DBA INTEGRATED POWER SERVICES_MI6 IPS as per quote 50030589-4 dated 10.30.25 for repairs needed on Generator 1A - SN: H000135346. Labor. , 8000 , 14352136 | C34: 220232.05 | D34: 0 | E34: -220232.05 | F34: 1 | G34: others
A35: Other items | B35: GAO5049_KB_0626_OpenPO WW_5MUniXOlEfGxWZ1NRsFAkA-300000131614726-ACCR-100002809437203 , 1040525989-2_TAMPA ARMATURE WORKS INC DBA INTEGRATED POWER SERVICES_MI6 IPS as per quote 50030589-4 dated 10.30.25 for repairs needed on Generator 1A - SN: H000135346. Labor. , 8000 , 14352137 | C35: 0 | D35: -220232.05 | E35: -220232.05 | F35: 1 | G35: others
A36: Other items | B36: GAO5049_KB_0726_OpenPO WW_M3Z9-4xYEfGhDpMHE24o3Q-300000131614726-ACCR-100002877409113 , 1040525989-2_TAMPA ARMATURE WORKS INC DBA INTEGRATED POWER SERVICES_MI6 IPS as per quote 50030589-4 dated 10.30.25 for repairs needed on Generator 1A - SN: H000135346. Labor. , 8000 , 15146952 | C36: 0 | D36: 220232.05 | E36: 220232.05 | F36: 1 | G36: others
A37: Other items | B37: Remaining transactions | C37: 24042766 | D37: 19679481 | E37: -4363285.5 | F37: 53582 | G37: others

Sheet Classifications
A1: Status
A2: No classifications needed review.

Sheet Unmatched lookups
A1: Status
A2: No lookups were used, or every value matched.

Sheet Data controls
A1: Check | B1: Result | C1: Message | D1: Details
A2: required_columns | B2: Passed | C2: All required columns are available. | D2: {"missing": []}
A3: periods_present | B3: Passed | C3: Both comparison slices contain data. | D3: {"missing": [], "rows": {"base": 28368, "current": 30167}}
A4: no_duplicate_periods_across_files | B4: Passed | C4: No periods overlap across stacked sources. | D4: {"periods": []}
A5: new_or_removed_members | B5: Warning | C5: New or removed dimension members were found; see details. | D5: {"Ibx_Code": {"new": ["AM12", "AM9", "CHICAGO OFFICE", "CHICAGO OFFICE CHO1", "IL3X ISTANBUL", "LD-A", "PA14", "PORTUGAL CLS - LSA", "SANTIAGO OFFICE"], "removed": ["BL1", "LD10", "TORONTO (TRO) OFFICE", "ZH1"]}}
A6: join_unmatched_keys | B6: Passed | C6: All lookup keys matched. | D6: {}
A7: join_fanout | B7: Passed | C7: Lookup joins preserve one row per source row. | D7: {}
A8: classification_coverage | B8: Passed | C8: Classification coverage meets the configured minimum. | D8: {}
A9: partial_period_used | B9: Passed | C9: No detected partial months are selected. | D9: {"months": [], "row_counts": {}}
A10: drivers_reconcile | B10: Passed | C10: Drivers and other items reconcile to the movement. | D10: {}
A11: flags_sum_to_rows | B11: Passed | C11: Flag counts reconcile to view rows. | D11: {}
A12: sections_reconcile | B12: Passed | C12: No section split configured. | D12: {}

Sheet Setup changes
A1: When (UTC) | B1: Changed by | C1: Reason | D1: Setting | E1: Change type | F1: Before | G1: After
A2: 46323.597 | B2: user | C2: Updated uploaded source definitions | D2: /sources/lookups | E2: add | G2: {}
A3: 46323.597 | B3: user | C3: Updated uploaded source definitions | D3: /sources/primary | E3: add | G3: {"files": [{"file": "sample_test_run_for_python_scrip_on_fresh_data_AA.xlsx", "sheet": "Detail", "header_row": 1, "start_col": "A", "end_col": null}], "union": {"mode": "stack", "tag_column": null}}
A4: 46323.598 | B4: preset | C4: Loaded saved setup 'Untitled analysis' version 1 | D4: /comparison/base/months | E4: replace | F4: [] | G4: ["2026-06"]
A5: 46323.598 | B5: preset | C5: Loaded saved setup 'Untitled analysis' version 1 | D5: /comparison/current/months | E5: replace | F5: [] | G5: ["2026-07"]
A6: 46323.598 | B6: preset | C6: Loaded saved setup 'Untitled analysis' version 1 | D6: /comparison/type | E6: replace | F6: QoQ | G6: period_vs_period
A7: 46323.598 | B7: preset | C7: Loaded saved setup 'Untitled analysis' version 1 | D7: /drill/group_by | E7: add | G7: {roles.driver_text}
A8: 46323.598 | B8: preset | C8: Loaded saved setup 'Untitled analysis' version 1 | D8: /drivers/measure | E8: add | G8: amount
A9: 46323.598 | B9: preset | C9: Loaded saved setup 'Untitled analysis' version 1 | D9: /drivers/view | E9: add | G9: By country
A10: 46323.598 | B10: preset | C10: Loaded saved setup 'Untitled analysis' version 1 | D10: /measures/amount | E10: add | G10: {"agg": "sum", "col": "{roles.value}"}
A11: 46323.598 | B11: preset | C11: Loaded saved setup 'Untitled analysis' version 1 | D11: /roles/dimensions | E11: replace | F11: [] | G11: ["Country", "Region", "Ibx_Code"]
A12: 46323.598 | B12: preset | C12: Loaded saved setup 'Untitled analysis' version 1 | D12: /roles/driver_text | E12: replace | F12: [] | G12: ["FAH_Line_Description"]
A13: 46323.598 | B13: preset | C13: Loaded saved setup 'Untitled analysis' version 1 | D13: /roles/period | E13: replace | G13: Period_Name
A14: 46323.598 | B14: preset | C14: Loaded saved setup 'Untitled analysis' version 1 | D14: /roles/value | E14: replace | G14: Functional_Net
A15: 46323.598 | B15: preset | C15: Loaded saved setup 'Untitled analysis' version 1 | D15: /views | E15: replace | F15: [] | G15: [{"name": "By country", "keys": ["Country", "Region", "Ibx_Code"], "measures": ["amount"], "compare": true}]
A16: 46323.599 | B16: user | C16: Changed the Explain step | D16: /commentary/style_profile | E16: add | G16: {"audience": "controller", "length": "medium", "structure": {"type": "overall", "split_by": null}, "tone": "neutral", "instructions": "Inspect the descriptions and tell us what the line descriptions are for. E.g what type of maintenance. ", "example_style": {"summary_of_style": "", "sample_phrases": []}, "include": ["to_verify", "one_offs", "timing"], "objective": "", "business_context": ""}

Sheet Explanation log
A1: Status
A2: No explanations have been saved or confirmed yet.

Sheet Run audit
A1: Item | B1: Value
A2: Run ID | B2: 2d9ad6a79f424c46a40c41620856df90
A3: Created (UTC) | B3: 2026-10-28T14:23:41.711823+00:00
A4: Engine version | B4: 2.0
A5: Preset | B5: generic_flux v1.0.0
A6: Setup fingerprint (SHA-256) | B6: 0964d7c5009905b14343263bfc4d4611cc49866d5ca11585bbf44538e7815f90
A7: Input file (primary) | B7: sample_test_run_for_python_scrip_on_fresh_data_AA.xlsx — SHA-256 6304d0f09a8c02d2c3c2cc1dbdfa1df9d6d85a470f495e468f0df99ac8fb8de0

Sheet AI assistant log
A1: Status
A2: The AI assistant was not used for this report.

Sheet FluxSpec
A1: FluxSpec (JSON)
A2: {
A3: "spec_version": "2.0",
A4: "preset": {
A5: "id": "generic_flux",
A6: "version": "1.0.0"
A7: },
A8: "flux_name": "Untitled analysis",
A9: "sources": {
A10: "lookups": {},
A11: "primary": {
A12: "files": [
... A214: }
