Workbook
Name BaseMonths: Settings!$B$7:$B$9
Name BaseVersion: Settings!$B$13
Name CurrentMonths: Settings!$B$10:$B$12
Name CurrentVersion: Settings!$B$14
Name Threshold: Settings!$B$15
Name TotalBase: Summary!$A$5
Name TotalCurrent: Summary!$B$5

Sheet Summary
A1: Untitled analysis
A2: Apr 2026 to Jun 2026 compared with Jan 2026 to Mar 2026 · Prepared 29 Oct 2026 09:23 UTC
A4: Base total | B4: Current total | C4: Movement | D4: Movement % | E4: Threshold
A5: =SUMPRODUCT((ISNUMBER(MATCH(Data!$B$2:$B$31,BaseMonths,0)))*Data!$C$2:$C$31) -> 9480021.6 | B5: =SUMPRODUCT((ISNUMBER(MATCH(Data!$B$2:$B$31,CurrentMonths,0)))*Data!$C$2:$C$31) -> 10979957 | C5: =B5-A5 -> 1499935.4 | D5: =IF(A5=0,"",C5/ABS(A5)) -> 0.15822068 | E5: =Threshold -> 300000
A7: Explanation status
A8: Needs explanation | B8: Explained by AI — please review | C8: Confirmed | D8: Below threshold
A9: =COUNTIF(Commentary!$H$2:$H$5,"Needs explanation") -> 0 | B9: =COUNTIF(Commentary!$H$2:$H$5,"Explained by AI — please review") -> 3 | C9: =COUNTIF(Commentary!$H$2:$H$5,"Confirmed") -> 0 | D9: =COUNTIF(Commentary!$H$2:$H$5,"Below threshold") -> 1
A10: 3 movements still need a person to write or check the explanation — open Needs Explanation
A12: Headline
A13: Variance commentary by country
A15: Key drivers
A16: Movement | B16: Base | C16: Current | D16: Change | E16: Change % | F16: Status | G16: Explanation
A17: United Kingdom | B17: ='Commentary'!$C$2 -> 2850000 | C17: ='Commentary'!$D$2 -> 3840000 | D17: ='Commentary'!$E$2 -> 990000 | E17: =IF(B17=0,"",D17/ABS(B17)) -> 0.34736842 | F17: Explained by AI — please review | G17: +$1.0M — United Kingdom. Descriptions include Data centre cooling maintenance / Operational.
A18: Germany | B18: ='Commentary'!$C$3 -> 1860000 | C18: ='Commentary'!$D$3 -> 2730000 | D18: ='Commentary'!$E$3 -> 870000 | E18: =IF(B18=0,"",D18/ABS(B18)) -> 0.46774194 | F18: Explained by AI — please review | G18: +$0.9M — Germany. Descriptions include Emergency generator servicing / Operational.
A19: Netherlands | B19: ='Commentary'!$C$4 -> 2220021.6 | C19: ='Commentary'!$D$4 -> 1619957 | D19: ='Commentary'!$E$4 -> -600064.55 | E19: =IF(B19=0,"",D19/ABS(B19)) -> -0.27029672 | F19: Explained by AI — please review | G19: -$0.6M — Netherlands. Descriptions include Preventive maintenance contract / Operational.
A20: Other items | B20: ='Commentary'!$C$5 -> 2550000 | C20: ='Commentary'!$D$5 -> 2790000 | D20: ='Commentary'!$E$5 -> 240000 | E20: =IF(B20=0,"",D20/ABS(B20)) -> 0.094117647 | F20: Below threshold | G20: +$0.2M — Other items. Remaining movements below the materiality threshold, grouped by the engine.
A22: What is in this workbook
A23: Review
A24: Summary | B24: This overview: totals, explanation status, key drivers and a guide to the tabs.
A25: Needs Explanation | B25: Movements that still need a person to write or check the explanation.
A26: Commentary | B26: Every reported movement with its amounts, status, explanation and who confirmed it.
A28: Evidence and reconciliation
A29: Drill-down | B29: Every line of the comparison, largest change first, and which movement it is reported in.
A30: Data checks | B30: Reconciliation: the workbook's formulas must agree with the engine's totals.
A31: Data | B31: The grouped source amounts every formula adds up.
A32: Settings | B32: Months, versions and the threshold the formulas use. Change Threshold to test sensitivity.
A34: Supporting detail
A35: Variance - By country | B35: Every line of the 'By country' comparison, as calculated by the engine.
A36: Movement detail | B36: Each reported movement with its grouping, line count, flags and evidence references.
A37: Source lines | B37: The source descriptions behind each movement, with their amounts.
A38: Classifications | B38: How lines were classified, for review.
A39: Unmatched lookups | B39: Lookup values that did not match the main data.
A41: Audit trail
A42: Data controls | B42: Every data control run before the report, with its details.
A43: Setup changes | B43: Every change made to the setup before this run, with who made it and why.
A44: Explanation log | B44: Every explanation saved or confirmed, with who did it and when.
A45: Run audit | B45: Run fingerprint: engine version, setup fingerprint and the fingerprint of every input file.
A46: AI assistant log | B46: What the AI assistant was asked and answered while building this report.
A47: FluxSpec | B47: The full setup used for this run, as JSON. The same file is available as a separate download.
A49: About these numbers
...

Sheet Needs Explanation
A1: Movement | B1: Change | C1: Base | D1: Current | E1: Status | F1: Current text | G1: What is needed | H1: Supporting descriptions
A2: United Kingdom | B2: ='Commentary'!$E$2 -> 990000 | C2: ='Commentary'!$C$2 -> 2850000 | D2: ='Commentary'!$D$2 -> 3840000 | E2: Explained by AI — please review | F2: +$1.0M — United Kingdom. Descriptions include Data centre cooling maintenance / Operational. | G2: Check the AI draft against the evidence, then confirm or edit it. | H2: Data centre cooling maintenance / Operational (+$1.0M)
A3: Germany | B3: ='Commentary'!$E$3 -> 870000 | C3: ='Commentary'!$C$3 -> 1860000 | D3: ='Commentary'!$D$3 -> 2730000 | E3: Explained by AI — please review | F3: +$0.9M — Germany. Descriptions include Emergency generator servicing / Operational. | G3: Check the AI draft against the evidence, then confirm or edit it. | H3: Emergency generator servicing / Operational (+$0.9M)
A4: Netherlands | B4: ='Commentary'!$E$4 -> -600064.55 | C4: ='Commentary'!$C$4 -> 2220021.6 | D4: ='Commentary'!$D$4 -> 1619957 | E4: Explained by AI — please review | F4: -$0.6M — Netherlands. Descriptions include Preventive maintenance contract / Operational. | G4: Check the AI draft against the evidence, then confirm or edit it. | H4: Preventive maintenance contract / Operational (-$0.6M); Cooling accrual — synthetic golden rule example / Accrual - Reversal (-$34.07); Cooling accrual — synthetic golden rule example / Accrual - Current (-$30.48)

Sheet Commentary
A1: Movement | B1: Country | C1: Base | D1: Current | E1: Change | F1: Change % | G1: Above threshold? | H1: Status | I1: Explanation | J1: Written by | K1: Confirmed by | L1: Confirmed (UTC) | M1: Evidence
A2: United Kingdom | B2: United Kingdom | C2: =SUMPRODUCT((Data!$A$2:$A$31=$B2)*(ISNUMBER(MATCH(Data!$B$2:$B$31,BaseMonths,0)))*Data!$C$2:$C$31) -> 2850000 | D2: =SUMPRODUCT((Data!$A$2:$A$31=$B2)*(ISNUMBER(MATCH(Data!$B$2:$B$31,CurrentMonths,0)))*Data!$C$2:$C$31) -> 3840000 | E2: =D2-C2 -> 990000 | F2: =IF(C2=0,"",E2/ABS(C2)) -> 0.34736842 | G2: =IF(ABS(E2)>=Threshold,"Yes","No") -> Yes | H2: Explained by AI — please review | I2: +$1.0M — United Kingdom. Descriptions include Data centre cooling maintenance / Operational. | J2: AI | M2: Data centre cooling maintenance / Operational (+$1.0M)
A3: Germany | B3: Germany | C3: =SUMPRODUCT((Data!$A$2:$A$31=$B3)*(ISNUMBER(MATCH(Data!$B$2:$B$31,BaseMonths,0)))*Data!$C$2:$C$31) -> 1860000 | D3: =SUMPRODUCT((Data!$A$2:$A$31=$B3)*(ISNUMBER(MATCH(Data!$B$2:$B$31,CurrentMonths,0)))*Data!$C$2:$C$31) -> 2730000 | E3: =D3-C3 -> 870000 | F3: =IF(C3=0,"",E3/ABS(C3)) -> 0.46774194 | G3: =IF(ABS(E3)>=Threshold,"Yes","No") -> Yes | H3: Explained by AI — please review | I3: +$0.9M — Germany. Descriptions include Emergency generator servicing / Operational. | J3: AI | M3: Emergency generator servicing / Operational (+$0.9M)
A4: Netherlands | B4: Netherlands | C4: =SUMPRODUCT((Data!$A$2:$A$31=$B4)*(ISNUMBER(MATCH(Data!$B$2:$B$31,BaseMonths,0)))*Data!$C$2:$C$31) -> 2220021.6 | D4: =SUMPRODUCT((Data!$A$2:$A$31=$B4)*(ISNUMBER(MATCH(Data!$B$2:$B$31,CurrentMonths,0)))*Data!$C$2:$C$31) -> 1619957 | E4: =D4-C4 -> -600064.55 | F4: =IF(C4=0,"",E4/ABS(C4)) -> -0.27029672 | G4: =IF(ABS(E4)>=Threshold,"Yes","No") -> Yes | H4: Explained by AI — please review | I4: -$0.6M — Netherlands. Descriptions include Preventive maintenance contract / Operational. | J4: AI | M4: Preventive maintenance contract / Operational (-$0.6M); Cooling accrual — synthetic golden rule example / Accrual - Reversal (-$34.07); Cooling accrual — synthetic golden rule example / Accrual - Current (-$30.48)
A5: Other items | C5: =TotalBase-SUM(C2:C4) -> 2550000 | D5: =TotalCurrent-SUM(D2:D4) -> 2790000 | E5: =D5-C5 -> 240000 | F5: =IF(C5=0,"",E5/ABS(C5)) -> 0.094117647 | G5: Grouped | H5: Below threshold | I5: +$0.2M — Other items. Remaining movements below the materiality threshold, grouped by the engine. | J5: AI | M5: Fire safety maintenance / Operational (+$0.2M); Electrical inspection / Operational (+$0.1M)

Sheet Drill-down
A1: Country | B1: Base | C1: Current | D1: Change | E1: Change % | F1: Above threshold? | G1: Reported as
A2: United Kingdom | B2: =SUMPRODUCT((Data!$A$2:$A$31=$A2)*(ISNUMBER(MATCH(Data!$B$2:$B$31,BaseMonths,0)))*Data!$C$2:$C$31) -> 2850000 | C2: =SUMPRODUCT((Data!$A$2:$A$31=$A2)*(ISNUMBER(MATCH(Data!$B$2:$B$31,CurrentMonths,0)))*Data!$C$2:$C$31) -> 3840000 | D2: =C2-B2 -> 990000 | E2: =IF(B2=0,"",D2/ABS(B2)) -> 0.34736842 | F2: =IF(ABS(D2)>=Threshold,"Yes","No") -> Yes | G2: United Kingdom
A3: Germany | B3: =SUMPRODUCT((Data!$A$2:$A$31=$A3)*(ISNUMBER(MATCH(Data!$B$2:$B$31,BaseMonths,0)))*Data!$C$2:$C$31) -> 1860000 | C3: =SUMPRODUCT((Data!$A$2:$A$31=$A3)*(ISNUMBER(MATCH(Data!$B$2:$B$31,CurrentMonths,0)))*Data!$C$2:$C$31) -> 2730000 | D3: =C3-B3 -> 870000 | E3: =IF(B3=0,"",D3/ABS(B3)) -> 0.46774194 | F3: =IF(ABS(D3)>=Threshold,"Yes","No") -> Yes | G3: Germany
A4: Netherlands | B4: =SUMPRODUCT((Data!$A$2:$A$31=$A4)*(ISNUMBER(MATCH(Data!$B$2:$B$31,BaseMonths,0)))*Data!$C$2:$C$31) -> 2220021.6 | C4: =SUMPRODUCT((Data!$A$2:$A$31=$A4)*(ISNUMBER(MATCH(Data!$B$2:$B$31,CurrentMonths,0)))*Data!$C$2:$C$31) -> 1619957 | D4: =C4-B4 -> -600064.55 | E4: =IF(B4=0,"",D4/ABS(B4)) -> -0.27029672 | F4: =IF(ABS(D4)>=Threshold,"Yes","No") -> Yes | G4: Netherlands
A5: Spain | B5: =SUMPRODUCT((Data!$A$2:$A$31=$A5)*(ISNUMBER(MATCH(Data!$B$2:$B$31,BaseMonths,0)))*Data!$C$2:$C$31) -> 1080000 | C5: =SUMPRODUCT((Data!$A$2:$A$31=$A5)*(ISNUMBER(MATCH(Data!$B$2:$B$31,CurrentMonths,0)))*Data!$C$2:$C$31) -> 1230000 | D5: =C5-B5 -> 150000 | E5: =IF(B5=0,"",D5/ABS(B5)) -> 0.13888889 | F5: =IF(ABS(D5)>=Threshold,"Yes","No") -> No | G5: Other items
A6: France | B6: =SUMPRODUCT((Data!$A$2:$A$31=$A6)*(ISNUMBER(MATCH(Data!$B$2:$B$31,BaseMonths,0)))*Data!$C$2:$C$31) -> 1470000 | C6: =SUMPRODUCT((Data!$A$2:$A$31=$A6)*(ISNUMBER(MATCH(Data!$B$2:$B$31,CurrentMonths,0)))*Data!$C$2:$C$31) -> 1560000 | D6: =C6-B6 -> 90000 | E6: =IF(B6=0,"",D6/ABS(B6)) -> 0.06122449 | F6: =IF(ABS(D6)>=Threshold,"Yes","No") -> No | G6: Other items

Sheet Data checks
A1: Check | B1: Engine value | C1: Workbook value | D1: Difference | E1: Result
A2: Base total | B2: 9480021.6 | C2: =TotalBase -> 9480021.6 | D2: =C2-B2 -> 0 | E2: =IF(ABS(D2)<0.005,"OK","Check") -> OK
A3: Current total | B3: 10979957 | C3: =TotalCurrent -> 10979957 | D3: =C3-B3 -> 0 | E3: =IF(ABS(D3)<0.005,"OK","Check") -> OK
A4: Movement lines add up to the total movement | B4: 1499935.4 | C4: =SUM(Commentary!$E$2:$E$5) -> 1499935.4 | D4: =C4-B4 -> 0 | E4: =IF(ABS(D4)<0.005,"OK","Check") -> OK
A5: Drill-down lines add up to the total movement | B5: 1499935.4 | C5: =SUM('Drill-down'!$D$2:$D$6) -> 1499935.4 | D5: =C5-B5 -> 0 | E5: =IF(ABS(D5)<0.005,"OK","Check") -> OK
A7: Data controls run before the report
A8: required_columns | B8: Passed | C8: All required columns are available.
A9: periods_present | B9: Passed | C9: Both comparison slices contain data.
A10: no_duplicate_periods_across_files | B10: Passed | C10: No periods overlap across stacked sources.
A11: new_or_removed_members | B11: Passed | C11: Dimension membership is consistent.
A12: join_unmatched_keys | B12: Passed | C12: All lookup keys matched.
A13: join_fanout | B13: Passed | C13: Lookup joins preserve one row per source row.
A14: classification_coverage | B14: Passed | C14: Classification coverage meets the configured minimum.
A15: partial_period_used | B15: Passed | C15: No detected partial months are selected.
A16: drivers_reconcile | B16: Passed | C16: Drivers and other items reconcile to the movement.
A17: flags_sum_to_rows | B17: Passed | C17: Flag counts reconcile to view rows.
A18: sections_reconcile | B18: Passed | C18: No section split configured.
A20: Full details are on the Data controls sheet.

Sheet Data
A1: Country | B1: Month | C1: Amount
A2: France | B2: 2026-01 | C2: 487900
A3: France | B3: 2026-02 | C3: 490000
A4: France | B4: 2026-03 | C4: 492100
A5: France | B5: 2026-04 | C5: 517900
A6: France | B6: 2026-05 | C6: 520000
A7: France | B7: 2026-06 | C7: 522100
A8: Germany | B8: 2026-01 | C8: 617900
A9: Germany | B9: 2026-02 | C9: 620000
A10: Germany | B10: 2026-03 | C10: 622100
A11: Germany | B11: 2026-04 | C11: 907900
A12: Germany | B12: 2026-05 | C12: 910000
A13: Germany | B13: 2026-06 | C13: 912100
... A31: United Kingdom | B31: 2026-06 | C31: 1282100

Sheet Settings
A1: Report settings
A3: Report | B3: Untitled analysis
A4: Run ID | B4: 23add893b2934907986f52e0d5b85df8
A5: Created (UTC) | B5: 46324.391
A6: Comparison | B6: quarter_vs_quarter
A7: Base months | B7: 2026-01
B8: 2026-02
B9: 2026-03
A10: Current months | B10: 2026-04
B11: 2026-05
B12: 2026-06
A13: Base version | B13: All versions
A14: Current version | B14: All versions
A15: Threshold | B15: 300000
A16: Movements shown (top N) | B16: 15
A17: Remaining movements label | B17: Other items
A18: Currency | B18: $
A19: How amounts are calculated | B19: Formulas over the Data sheet
A20: Why | B20: Every line was checked against the engine before saving.
A21: Setup fingerprint (SHA-256) | B21: dee57d288ab01299b16e1d959afa993420d8c9d060d8e9b804e08cafc2ba6c9e
A23: Change Threshold to see which movements cross it. The list of movements was chosen when the report ran; run the report again to change months, versions or the list.

Sheet Variance - By country
A1: Country | B1: Base | C1: Current | D1: Change | E1: Change %
A2: United Kingdom | B2: 2850000 | C2: 3840000 | D2: 990000 | E2: 0.34736842
A3: Netherlands | B3: 2220021.6 | C3: 1619957 | D3: -600064.55 | E3: -0.27029672
A4: Germany | B4: 1860000 | C4: 2730000 | D4: 870000 | E4: 0.46774194
A5: France | B5: 1470000 | C5: 1560000 | D5: 90000 | E5: 0.06122449
A6: Spain | B6: 1080000 | C6: 1230000 | D6: 150000 | E6: 0.13888889

Sheet Movement detail
A1: Movement | B1: Country | C1: Base | D1: Current | E1: Change | F1: Change % | G1: Lines | H1: Flags | I1: Top descriptions | J1: Evidence references | K1: Movement ID
A2: United Kingdom | B2: United Kingdom | C2: 2850000 | D2: 3840000 | E2: 990000 | F2: 0.34736842 | G2: 6 | I2: Data centre cooling maintenance / Operational (+$1.0M) | J2: driver:d1 | K2: d1
A3: Germany | B3: Germany | C3: 1860000 | D3: 2730000 | E3: 870000 | F3: 0.46774194 | G3: 6 | I3: Emergency generator servicing / Operational (+$0.9M) | J3: driver:d2 | K3: d2
A4: Netherlands | B4: Netherlands | C4: 2220021.6 | D4: 1619957 | E4: -600064.55 | F4: -0.27029672 | G4: 10 | I4: Preventive maintenance contract / Operational (-$0.6M); Cooling accrual — synthetic golden rule example / Accrual - Reversal (-$34.07); Cooling accrual — synthetic golden rule example / Accrual - Current (-$30.48) | J4: driver:d3 | K4: d3
A5: Other items | C5: 2550000 | D5: 2790000 | E5: 240000 | F5: 0.094117647 | G5: 12 | I5: Fire safety maintenance / Operational (+$0.2M); Electrical inspection / Operational (+$0.1M) | J5: driver:others | K5: others

Sheet Source lines
A1: Movement | B1: Description | C1: Base | D1: Current | E1: Change | F1: Lines | G1: Movement ID
A2: United Kingdom | B2: Data centre cooling maintenance / Operational | C2: 2850000 | D2: 3840000 | E2: 990000 | F2: 6 | G2: d1
A3: Germany | B3: Emergency generator servicing / Operational | C3: 1860000 | D3: 2730000 | E3: 870000 | F3: 6 | G3: d2
A4: Netherlands | B4: Preventive maintenance contract / Operational | C4: 2220000 | D4: 1620000 | E4: -600000 | F4: 6 | G4: d3
A5: Netherlands | B5: Cooling accrual — synthetic golden rule example / Accrual - Reversal | C5: -1813.59 | D5: -1847.66 | E5: -34.07 | F5: 2 | G5: d3
A6: Netherlands | B6: Cooling accrual — synthetic golden rule example / Accrual - Current | C6: 1835.16 | D6: 1804.68 | E6: -30.48 | F6: 2 | G6: d3
A7: Other items | B7: Fire safety maintenance / Operational | C7: 1080000 | D7: 1230000 | E7: 150000 | F7: 6 | G7: others
A8: Other items | B8: Electrical inspection / Operational | C8: 1470000 | D8: 1560000 | E8: 90000 | F8: 6 | G8: others

Sheet Classifications
A1: Status
A2: No classifications needed review.

Sheet Unmatched lookups
A1: Status
A2: No lookups were used, or every value matched.

Sheet Data controls
A1: Check | B1: Result | C1: Message | D1: Details
A2: required_columns | B2: Passed | C2: All required columns are available. | D2: {"missing": []}
A3: periods_present | B3: Passed | C3: Both comparison slices contain data. | D3: {"missing": [], "rows": {"base": 17, "current": 17}}
A4: no_duplicate_periods_across_files | B4: Passed | C4: No periods overlap across stacked sources. | D4: {"periods": []}
A5: new_or_removed_members | B5: Passed | C5: Dimension membership is consistent. | D5: {}
A6: join_unmatched_keys | B6: Passed | C6: All lookup keys matched. | D6: {}
A7: join_fanout | B7: Passed | C7: Lookup joins preserve one row per source row. | D7: {}
A8: classification_coverage | B8: Passed | C8: Classification coverage meets the configured minimum. | D8: {}
A9: partial_period_used | B9: Passed | C9: No detected partial months are selected. | D9: {"months": [], "row_counts": {}}
A10: drivers_reconcile | B10: Passed | C10: Drivers and other items reconcile to the movement. | D10: {}
A11: flags_sum_to_rows | B11: Passed | C11: Flag counts reconcile to view rows. | D11: {}
A12: sections_reconcile | B12: Passed | C12: No section split configured. | D12: {}

Sheet Setup changes
A1: When (UTC) | B1: Changed by | C1: Reason | D1: Setting | E1: Change type | F1: Before | G1: After
A2: 46324.39 | B2: user | C2: Updated uploaded source definitions | D2: /sources/lookups | E2: add | G2: {"open_po": {"files": [{"file": "Sample_Open_PO.xlsx", "sheet": "Open PO Report ", "header_row": 1, "start_col": "A", "end_col": null}]}}
A3: 46324.39 | B3: user | C3: Updated uploaded source definitions | D3: /sources/primary | E3: add | G3: {"files": [{"file": "Sample_GL_2026.csv", "sheet": "(csv)", "header_row": 1, "start_col": "A", "end_col": null}], "union": {"mode": "stack", "tag_column": null}}
A4: 46324.39 | B4: agent | C4: Set up comparison of Q2 2026 against Q1 2026 grouped by Country. Please select the Amount column to proceed. | D4: /comparison/base/months | E4: replace | F4: [] | G4: ["2026-01", "2026-02", "2026-03"]
A5: 46324.39 | B5: agent | C5: Set up comparison of Q2 2026 against Q1 2026 grouped by Country. Please select the Amount column to proceed. | D5: /comparison/current/months | E5: replace | F5: [] | G5: ["2026-04", "2026-05", "2026-06"]
A6: 46324.39 | B6: agent | C6: Set up comparison of Q2 2026 against Q1 2026 grouped by Country. Please select the Amount column to proceed. | D6: /comparison/type | E6: replace | F6: QoQ | G6: quarter_vs_quarter
A7: 46324.39 | B7: agent | C7: Set up comparison of Q2 2026 against Q1 2026 grouped by Country. Please select the Amount column to proceed. | D7: /drivers/view | E7: add | G7: By country
A8: 46324.39 | B8: agent | C8: Set up comparison of Q2 2026 against Q1 2026 grouped by Country. Please select the Amount column to proceed. | D8: /roles/dimensions | E8: replace | F8: [] | G8: ["Country"]
A9: 46324.39 | B9: agent | C9: Set up comparison of Q2 2026 against Q1 2026 grouped by Country. Please select the Amount column to proceed. | D9: /roles/period | E9: replace | G9: Period_Name
A10: 46324.39 | B10: agent | C10: Set up comparison of Q2 2026 against Q1 2026 grouped by Country. Please select the Amount column to proceed. | D10: /views | E10: replace | F10: [] | G10: [{"name": "By country", "keys": ["Country"], "measures": ["amount"], "compare": true}]
A11: 46324.39 | B11: agent | C11: We identified Period_Name as the Month column and proposed Functional_Net as the Amount column, Country and Region as Group by columns, and FAH_Line_Description for movement descriptions. Please confirm which amount column you would like to use. | D11: /roles/credit | E11: replace | G11: Accounted_Cr
A12: 46324.39 | B12: agent | C12: We identified Period_Name as the Month column and proposed Functional_Net as the Amount column, Country and Region as Group by columns, and FAH_Line_Description for movement descriptions. Please confirm which amount column you would like to use. | D12: /roles/debit | E12: replace | G12: Accounted_Dr
A13: 46324.39 | B13: agent | C13: We identified Period_Name as the Month column and proposed Functional_Net as the Amount column, Country and Region as Group by columns, and FAH_Line_Description for movement descriptions. Please confirm which amount column you would like to use. | D13: /roles/dimensions | E13: replace | F13: ["Country"] | G13: ["Country", "Region", "Account"]
A14: 46324.39 | B14: agent | C14: We identified Period_Name as the Month column and proposed Functional_Net as the Amount column, Country and Region as Group by columns, and FAH_Line_Description for movement descriptions. Please confirm which amount column you would like to use. | D14: /roles/driver_text | E14: replace | F14: [] | G14: ["FAH_Line_Description", "FAH_Event_Type"]
A15: 46324.39 | B15: agent | C15: We identified Period_Name as the Month column and proposed Functional_Net as the Amount column, Country and Region as Group by columns, and FAH_Line_Description for movement descriptions. Please confirm which amount column you would like to use. | D15: /roles/keys | E15: replace | F15: [] | G15: ["Po_Number"]
A16: 46324.39 | B16: agent | C16: We identified Period_Name as the Month column and proposed Functional_Net as the Amount column, Country and Region as Group by columns, and FAH_Line_Description for movement descriptions. Please confirm which amount column you would like to use. | D16: /roles/value | E16: replace | G16: Functional_Net
A17: 46324.391 | B17: agent | C17: Set up the amount measure using Functional_Net, grouped by Country, explaining movements above $300,000 for up to fifteen items. | D17: /drivers/measure | E17: add | G17: amount
A18: 46324.391 | B18: agent | C18: Set up the amount measure using Functional_Net, grouped by Country, explaining movements above $300,000 for up to fifteen items. | D18: /measures/amount | E18: add | G18: {"agg": "sum", "col": "Functional_Net"}

Sheet Explanation log
A1: Status
A2: No explanations have been saved or confirmed yet.

Sheet Run audit
A1: Item | B1: Value
A2: Run ID | B2: 23add893b2934907986f52e0d5b85df8
A3: Created (UTC) | B3: 2026-10-29T09:23:23.418345+00:00
A4: Engine version | B4: 2.0
A5: Preset | B5: generic_flux v1.0.0
A6: Setup fingerprint (SHA-256) | B6: dee57d288ab01299b16e1d959afa993420d8c9d060d8e9b804e08cafc2ba6c9e
A7: Input file (primary) | B7: Sample_GL_2026.csv — SHA-256 0136e4a15d177b4fc05eae2908fe6afed79ef71a1ee4028333e677ccf807b1bd
A8: Input file (lookup) | B8: Sample_Open_PO.xlsx — SHA-256 546b8d66f1027955ee8b8038883a511aa4956b72470bc8e599b840fa49686e5f

Sheet AI assistant log
A1: Entry | B1: Part | C1: Log entry (JSON)
A2: 1 | B2: 1 | C2: {"timestamp": "2026-10-29T09:21:43.469517+00:00", "response": {"contract_version": "journey-1", "request_id": "4c39fbef-18f1-4471-a487-834a3325b6b2", "step": "plan_from_description", "status": "needs_input", "proposal": {"patch": [{"op": "replace", "path": "/comparison", "value": {"type": "quarter_vs_quarter", "base": {"months": ["2026-01", "2026-02", "2026-03"]}, "current": {"months": ["2026-04", "2026-05", "2026-06"]}}}, {"op": "replace", "path": "/roles/dimensions", "value": ["Country"]}, {"op": "replace", "path": "/roles/period", "value": "Period_Name"}, {"op": "replace", "path": "/views", "value": [{"name": "By country", "keys": ["Country"], "measures": ["amount"], "compare": true}]}, {"op": "replace", "path": "/drivers", "value": {"view": "By country", "materiality": {"mode": "abs", "abs": 300000}, "top_n": 15, "others_label": "Other items"}}], "step_states": [{"step": "data", "status": "needs_input", "summary": "Choose the Amount column.", "reason": "Functional_Net and Accounted_Dr are both available numeric columns.", "question_ids": ["amount_column"]}, {"step": "compare", "status": "confident", "summary": "Compare Q2 2026 (Apr–Jun) with Q1 2026 (Jan–Mar).", "reason": "The available months cover Q1 and Q2 2026.", "question_ids": []}, {"step": "include", "status": "confident", "summary": "Include all main data.", "reason": "No specific filters were requested.", "question_ids": []}, {"step": "group", "status": "confident", "summary": "Group by Country.", "reason": "You requested grouping by country.", "question_ids": []}, {"step": "important", "status": "confident", "summary": "Explain movements above 300,000.", "reason": "Preserved default threshold and top 15 movements.", "question_ids": []}, {"step": "explain", "status": "confident", "summary": "Use standard controller commentary.", "reason": "Preserved default commentary settings.", "question_ids": []}]}, "confidence": "medium", "rationale": "Configured quarter-on-quarter comparison for Q2 2026 versus Q1 2026 grouped by Country and updated driver settings to reference the new view. Confirmation is needed for the Amount column.", "questions": [{"id": "amount_column", "text": "Which column should be used as the Amount column?", "options": ["Use Functional_Net as the Amount column.", "Use Accounted_Dr as the Amount column."]}], "warnings": [], "summary": "Set up comparison of Q2 2026 against Q1 2026 grouped by Country. Please select the Amount column to proceed.", "changes": [{"setting": "/comparison/base/months", "from": "", "to": "2026-01, 2026-02, 2026-03", "reason": "Set up comparison of Q2 2026 against Q1 2026 grouped by Country. Please select the Amount column to proceed."}, {"setting": "/comparison/current/months", "from": "", "to": "2026-04, 2026-05, 2026-06", "reason": "Set up comparison of Q2 2026 against Q1 2026 grouped by Country. Please select the Amount column to proceed."}, {"setting": "/comparison/type", "from": "QoQ", "to": "quarter_vs_quarter", "reason": "Set up comparison of Q2 2026 against Q1 2026 grouped by Country. Please select the Amount column to proceed."}, {"setting": "/drivers/view", "from": "not set", "to": "By country", "reason": "Set up comparison of Q2 2026 against Q1 2026 grouped by Country. Please select the Amount column to proceed."}, {"setting": "/roles/dimensions", "from": "", "to": "Country", "reason": "Set up comparison of Q2 2026 against Q1 2026 grouped by Country. Please select the Amount column to proceed."}, {"setting": "/roles/period", "from": "not set", "to": "Period_Name", "reason": "Set up comparison of Q2 2026 against Q1 2026 grouped by Country. Please select the Amount column to proceed."}, {"setting": "/views", "from": "", "to": "name: By country; keys: Country; measures: amount; compare: True", "reason": "Set up comparison of Q2 2026 against Q1 2026 grouped by Country. Please select the Amount column to proceed."}], "applied": true, "patch": [{"op": "replace", "path": "/comparison/base/months", "value": ["2026-01", "2026-02", "2026-03"]}, {"op": "replace", "path": "/comparison/current/months", "value": ["2026-04", "2026-05", "2026-06"]}, {"op": "replace", "path": "/comparison/type", "value": "quarter_vs_quarter"}, {"op": "add", "path": "/drivers/view", "value": "By country"}, {"op": "replace", "path": "/roles/dimensions", "value": ["Country"]}, {"op": "replace", "path": "/roles/period", "value": "Period_Name"}, {"op": "replace", "path": "/views", "value": [{"name": "By country", "keys": ["Country"], "measures": ["amount"], "compare": true}]}]}}
A3: 2 | B3: 1 | C3: {"timestamp": "2026-10-29T09:21:58.325603+00:00", "response": {"contract_version": "journey-1", "request_id": "deeea1a0-83b6-4712-a468-7161413682d5", "step": "map_columns", "status": "needs_input", "proposal": {"roles": {"value": "Functional_Net", "period": "Period_Name", "scenario": null, "debit": "Accounted_Dr", "credit": "Accounted_Cr", "keys": ["Po_Number"], "dimensions": ["Country", "Region", "Account"], "driver_text": ["FAH_Line_Description", "FAH_Event_Type"]}, "unmapped": []}, "confidence": "medium", "rationale": "Multiple numeric fields are present in the dataset (Functional_Net, Accounted_Dr, and Accounted_Cr). We propose Functional_Net as the primary Amount column, with Accounted_Dr and Accounted_Cr available as debit and credit, but user confirmation is required.", "questions": [{"id": "select_amount_column", "text": "Which column should be used as the primary Amount column?", "options": ["Use Functional_Net as the Amount column.", "Use Accounted_Dr and Accounted_Cr as separate debit and credit columns."]}], "warnings": [], "summary": "We identified Period_Name as the Month column and proposed Functional_Net as the Amount column, Country and Region as Group by columns, and FAH_Line_Description for movement descriptions. Please confirm which amount column you would like to use.", "changes": [{"setting": "/roles/credit", "from": "not set", "to": "Accounted_Cr", "reason": "We identified Period_Name as the Month column and proposed Functional_Net as the Amount column, Country and Region as Group by columns, and FAH_Line_Description for movement descriptions. Please confirm which amount column you would like to use."}, {"setting": "/roles/debit", "from": "not set", "to": "Accounted_Dr", "reason": "We identified Period_Name as the Month column and proposed Functional_Net as the Amount column, Country and Region as Group by columns, and FAH_Line_Description for movement descriptions. Please confirm which amount column you would like to use."}, {"setting": "/roles/dimensions", "from": "Country", "to": "Country, Region, Account", "reason": "We identified Period_Name as the Month column and proposed Functional_Net as the Amount column, Country and Region as Group by columns, and FAH_Line_Description for movement descriptions. Please confirm which amount column you would like to use."}, {"setting": "/roles/driver_text", "from": "", "to": "FAH_Line_Description, FAH_Event_Type", "reason": "We identified Period_Name as the Month column and proposed Functional_Net as the Amount column, Country and Region as Group by columns, and FAH_Line_Description for movement descriptions. Please confirm which amount column you would like to use."}, {"setting": "/roles/keys", "from": "", "to": "Po_Number", "reason": "We identified Period_Name as the Month column and proposed Functional_Net as the Amount column, Country and Region as Group by columns, and FAH_Line_Description for movement descriptions. Please confirm which amount column you would like to use."}, {"setting": "/roles/value", "from": "not set", "to": "Functional_Net", "reason": "We identified Period_Name as the Month column and proposed Functional_Net as the Amount column, Country and Region as Group by columns, and FAH_Line_Description for movement descriptions. Please confirm which amount column you would like to use."}], "applied": true, "patch": [{"op": "replace", "path": "/roles/credit", "value": "Accounted_Cr"}, {"op": "replace", "path": "/roles/debit", "value": "Accounted_Dr"}, {"op": "replace", "path": "/roles/dimensions", "value": ["Country", "Region", "Account"]}, {"op": "replace", "path": "/roles/driver_text", "value": ["FAH_Line_Description", "FAH_Event_Type"]}, {"op": "replace", "path": "/roles/keys", "value": ["Po_Number"]}, {"op": "replace", "path": "/roles/value", "value": "Functional_Net"}]}}
A4: 3 | B4: 1 | C4: {"timestamp": "2026-10-29T09:23:04.490286+00:00", "response": {"contract_version": "journey-1", "request_id": "163fece1-9871-4741-805d-e51668fc8477", "step": "define_rules", "status": "ok", "proposal": {"measures": {"amount": {"agg": "sum", "col": "Functional_Net"}}, "views": [{"name": "By country", "keys": ["Country"], "measures": ["amount"], "compare": true}], "sections": null, "decompose": null, "flags": [], "gates": [], "drivers": {"view": "By country", "measure": "amount", "materiality": {"mode": "abs", "abs": 300000}, "top_n": 15, "others_label": "Other items"}, "drill": {"top_n": 5}, "commentary": {"units": "M", "decimals": 1, "verify_tag": "[TO VERIFY]", "sign_style": "plus_minus", "currency_symbol": "$", "forbidden_terms": [], "max_line_words": 35}, "controls": [{"id": "required_columns", "severity": "stop"}, {"id": "periods_present", "severity": "stop"}, {"id": "no_duplicate_periods_across_files", "severity": "stop"}, {"id": "new_or_removed_members", "severity": "warn"}, {"id": "drivers_reconcile", "severity": "stop"}, {"id": "flags_sum_to_rows", "severity": "stop"}, {"id": "sections_reconcile", "severity": "stop"}, {"id": "join_unmatched_keys", "severity": "warn"}, {"id": "join_fanout", "severity": "stop"}, {"id": "classification_coverage", "severity": "warn", "params": {"minimum_percentage": 95}}, {"id": "partial_period_used", "severity": "warn"}], "value_rules": {"source": "column", "null_as_zero": true, "flip_sign_when": []}, "joins": [], "classification": null}, "confidence": "high", "rationale": "Defined the primary additive sum measure using Functional_Net to support movement reconciliation in the By country view, while preserving all existing drivers, settings, and mandatory controls.", "questions": [], "warnings": [], "summary": "Set up the amount measure using Functional_Net, grouped by Country, explaining movements above $300,000 for up to fifteen items.", "changes": [{"setting": "/drivers/measure", "from": "not set", "to": "amount", "reason": "Set up the amount measure using Functional_Net, grouped by Country, explaining movements above $300,000 for up to fifteen items."}, {"setting": "/measures/amount", "from": "not set", "to": "agg: sum; col: Functional_Net", "reason": "Set up the amount measure using Functional_Net, grouped by Country, explaining movements above $300,000 for up to fifteen items."}], "applied": true, "patch": [{"op": "add", "path": "/drivers/measure", "value": "amount"}, {"op": "add", "path": "/measures/amount", "value": {"agg": "sum", "col": "Functional_Net"}}]}}
A5: 4 | B5: 1 | C5: {"transport_attempt": {"request_id": "4c39fbef-18f1-4471-a487-834a3325b6b2", "step": "plan_from_description", "envelope_size": 12546, "duration": 13.505, "status": "repair", "response": "{\n \"contract_version\": \"journey-1\",\n \"request_id\": \"4c39fbef-18f1-4471-a487-834a3325b6b2\",\n \"step\": \"plan_from_description\",\n \"status\": \"needs_input\",\n \"proposal\": {\n \"patch\": [\n {\n \"op\": \"replace\",\n \"path\": \"/comparison\",\n \"value\": {\n \"type\": \"quarter_vs_quarter\",\n \"base\": {\n \"months\": [\n \"2026-01\",\n \"2026-02\",\n \"2026-03\"\n ]\n },\n \"current\": {\n \"months\": [\n \"2026-04\",\n \"2026-05\",\n \"2026-06\"\n ]\n }\n }\n },\n {\n \"op\": \"replace\",\n \"path\": \"/roles/dimensions\",\n \"value\": [\n \"Country\"\n ]\n },\n {\n \"op\": \"replace\",\n \"path\": \"/roles/period\",\n \"value\": \"Period_Name\"\n },\n {\n \"op\": \"replace\",\n \"path\": \"/views\",\n \"value\": [\n {\n \"name\": \"By country\",\n \"keys\": [\n \"Country\"\n ],\n \"measures\": [\n \"amount\"\n ],\n \"compare\": true\n }\n ]\n },\n {\n \"op\": \"replace\",\n \"path\": \"/drivers/view\",\n \"value\": \"By country\"\n }\n ],\n \"step_states\": [\n {\n \"step\": \"data\",\n \"status\": \"needs_input\",\n \"summary\": \"Choose the Amount column.\",\n \"reason\": \"Functional_Net and Accounted_Dr are both available numeric columns.\",\n \"question_ids\": [\n \"amount_column\"\n ]\n },\n {\n \"step\": \"compare\",\n \"status\": \"confident\",\n \"summary\": \"Compare Q2 2026 (Apr–Jun) with Q1 2026 (Jan–Mar).\",\n \"reason\": \"The available months cover Q1 and Q2 2026.\",\n \"question_ids\": []\n },\n {\n \"step\": \"include\",\n \"status\": \"confident\",\n \"summary\": \"Include all main data.\",\n \"reason\": \"No specific filters were requested.\",\n \"question_ids\": []\n },\n {\n \"step\": \"group\",\n \"status\": \"confident\",\n \"summary\": \"Group by Country.\",\n \"reason\": \"You requested grouping by country.\",\n \"question_ids\": []\n },\n {\n \"step\": \"important\",\n \"status\": \"confident\",\n \"summary\": \"Explain movements above 300,000.\",\n \"reason\": \"Preserved default threshold and top 15 movements.\",\n \"question_ids\": []\n },\n {\n \"step\": \"explain\",\n \"status\": \"confident\",\n \"summary\": \"Use standard controller commentary.\",\n \"reason\": \"Preserved default commentary settings.\",\n \"question_ids\": []\n }\n ]\n },\n \"confidence\": \"medium\",\n \"rationale\": \"Configured quarter-on-quarter comparison for Q2 2026 versus Q1 2026 grouped by Country. Confirmation is needed for the Amount column.\",\n \"questions\": [\n {\n \"id\": \"amount_column\",\n \"text\": \"Which column should be used as the Amount column?\",\n \"options\": [\n \"Use Functional_Net as the Amount column.\",\n \"Use Accounted_Dr as the Amount column.\"\n ]\n }\n ],\n \"warnings\": [],\n \"summary\": \"Set up comparison of Q2 2026 against Q1 2026 grouped by Country. Please select the Amount column to proceed.\",\n \"changes\": [\n {\n \"setting\": \"Compare with\",\n \"from\": \"Not set\",\n \"to\": \"Q2 2026 (Apr–Jun) vs Q1 2026 (Jan–Mar)\",\n \"reason\": \"Your request to compare the latest quarter with the previous quarter\"\n },\n {\n \"setting\": \"Group by\",\n \"from\": \"Total\",\n \"to\": \"Country\",\n \"reason\": \"Your request to group by country\"\n }\n ]\n}"}}
A6: 5 | B6: 1 | C6: {"transport_attempt": {"request_id": "4c39fbef-18f1-4471-a487-834a3325b6b2", "step": "repair", "envelope_size": 16579, "duration": 11.931, "status": "ok", "response": "{\n \"contract_version\": \"journey-1\",\n \"request_id\": \"4c39fbef-18f1-4471-a487-834a3325b6b2\",\n \"step\": \"plan_from_description\",\n \"status\": \"needs_input\",\n \"proposal\": {\n \"patch\": [\n {\n \"op\": \"replace\",\n \"path\": \"/comparison\",\n \"value\": {\n \"type\": \"quarter_vs_quarter\",\n \"base\": {\n \"months\": [\n \"2026-01\",\n \"2026-02\",\n \"2026-03\"\n ]\n },\n \"current\": {\n \"months\": [\n \"2026-04\",\n \"2026-05\",\n \"2026-06\"\n ]\n }\n }\n },\n {\n \"op\": \"replace\",\n \"path\": \"/roles/dimensions\",\n \"value\": [\n \"Country\"\n ]\n },\n {\n \"op\": \"replace\",\n \"path\": \"/roles/period\",\n \"value\": \"Period_Name\"\n },\n {\n \"op\": \"replace\",\n \"path\": \"/views\",\n \"value\": [\n {\n \"name\": \"By country\",\n \"keys\": [\n \"Country\"\n ],\n \"measures\": [\n \"amount\"\n ],\n \"compare\": true\n }\n ]\n },\n {\n \"op\": \"replace\",\n \"path\": \"/drivers\",\n \"value\": {\n \"view\": \"By country\",\n \"materiality\": {\n \"mode\": \"abs\",\n \"abs\": 300000\n },\n \"top_n\": 15,\n \"others_label\": \"Other items\"\n }\n }\n ],\n \"step_states\": [\n {\n \"step\": \"data\",\n \"status\": \"needs_input\",\n \"summary\": \"Choose the Amount column.\",\n \"reason\": \"Functional_Net and Accounted_Dr are both available numeric columns.\",\n \"question_ids\": [\n \"amount_column\"\n ]\n },\n {\n \"step\": \"compare\",\n \"status\": \"confident\",\n \"summary\": \"Compare Q2 2026 (Apr–Jun) with Q1 2026 (Jan–Mar).\",\n \"reason\": \"The available months cover Q1 and Q2 2026.\",\n \"question_ids\": []\n },\n {\n \"step\": \"include\",\n \"status\": \"confident\",\n \"summary\": \"Include all main data.\",\n \"reason\": \"No specific filters were requested.\",\n \"question_ids\": []\n },\n {\n \"step\": \"group\",\n \"status\": \"confident\",\n \"summary\": \"Group by Country.\",\n \"reason\": \"You requested grouping by country.\",\n \"question_ids\": []\n },\n {\n \"step\": \"important\",\n \"status\": \"confident\",\n \"summary\": \"Explain movements above 300,000.\",\n \"reason\": \"Preserved default threshold and top 15 movements.\",\n \"question_ids\": []\n },\n {\n \"step\": \"explain\",\n \"status\": \"confident\",\n \"summary\": \"Use standard controller commentary.\",\n \"reason\": \"Preserved default commentary settings.\",\n \"question_ids\": []\n }\n ]\n },\n \"confidence\": \"medium\",\n \"rationale\": \"Configured quarter-on-quarter comparison for Q2 2026 versus Q1 2026 grouped by Country and updated driver settings to reference the new view. Confirmation is needed for the Amount column.\",\n \"questions\": [\n {\n \"id\": \"amount_column\",\n \"text\": \"Which column should be used as the Amount column?\",\n \"options\": [\n \"Use Functional_Net as the Amount column.\",\n \"Use Accounted_Dr as the Amount column.\"\n ]\n }\n ],\n \"warnings\": [],\n \"summary\": \"Set up comparison of Q2 2026 against Q1 2026 grouped by Country. Please select the Amount column to proceed.\",\n \"changes\": [\n {\n \"setting\": \"Compare with\",\n \"from\": \"Not set\",\n \"to\": \"Q2 2026 (Apr–Jun) vs Q1 2026 (Jan–Mar)\",\n \"reason\": \"Your request to compare the latest quarter with the previous quarter\"\n },\n {\n \"setting\": \"Group by\",\n \"from\": \"Total\",\n \"to\": \"Country\",\n \"reason\": \"Your request to group by country\"\n }\n ]\n}"}}
A7: 6 | B7: 1 | C7: {"transport_attempt": {"request_id": "deeea1a0-83b6-4712-a468-7161413682d5", "step": "map_columns", "envelope_size": 7124, "duration": 9.314, "status": "ok", "response": "{\n \"contract_version\": \"journey-1\",\n \"request_id\": \"deeea1a0-83b6-4712-a468-7161413682d5\",\n \"step\": \"map_columns\",\n \"status\": \"needs_input\",\n \"proposal\": {\n \"roles\": {\n \"value\": \"Functional_Net\",\n \"period\": \"Period_Name\",\n \"scenario\": null,\n \"debit\": \"Accounted_Dr\",\n \"credit\": \"Accounted_Cr\",\n \"keys\": [\"Po_Number\"],\n \"dimensions\": [\"Country\", \"Region\", \"Account\"],\n \"driver_text\": [\"FAH_Line_Description\", \"FAH_Event_Type\"]\n },\n \"unmapped\": []\n },\n \"confidence\": \"medium\",\n \"rationale\": \"Multiple numeric fields are present in the dataset (Functional_Net, Accounted_Dr, and Accounted_Cr). We propose Functional_Net as the primary Amount column, with Accounted_Dr and Accounted_Cr available as debit and credit, but user confirmation is required.\",\n \"questions\": [\n {\n \"id\": \"select_amount_column\",\n \"text\": \"Which column should be used as the primary Amount column?\",\n \"options\": [\n \"Use Functional_Net as the Amount column.\",\n \"Use Accounted_Dr and Accounted_Cr as separate debit and credit columns.\"\n ]\n }\n ],\n \"warnings\": [],\n \"summary\": \"We identified Period_Name as the Month column and proposed Functional_Net as the Amount column, Country and Region as Group by columns, and FAH_Line_Description for movement descriptions. Please confirm which amount column you would like to use.\",\n \"changes\": [\n {\n \"setting\": \"Amount column\",\n \"from\": \"Unmapped\",\n \"to\": \"Functional_Net\",\n \"reason\": \"Proposed as the primary net amount measure\"\n },\n {\n \"setting\": \"Description column\",\n \"from\": \"Unmapped\",\n \"to\": \"FAH_Line_Description, FAH_Event_Type\",\n \"reason\": \"Identified as descriptive text explaining line movements\"\n }\n ]\n}"}}
A8: 7 | B8: 1 | C8: {"transport_attempt": {"request_id": "163fece1-9871-4741-805d-e51668fc8477", "step": "define_rules", "envelope_size": 8524, "duration": 11.013, "status": "ok", "response": "{\n \"contract_version\": \"journey-1\",\n \"request_id\": \"163fece1-9871-4741-805d-e51668fc8477\",\n \"step\": \"define_rules\",\n \"status\": \"ok\",\n \"proposal\": {\n \"measures\": {\n \"amount\": {\n \"agg\": \"sum\",\n \"col\": \"Functional_Net\"\n }\n },\n \"views\": [\n {\n \"name\": \"By country\",\n \"keys\": [\"Country\"],\n \"measures\": [\"amount\"],\n \"compare\": true\n }\n ],\n \"sections\": null,\n \"decompose\": null,\n \"flags\": [],\n \"gates\": [],\n \"drivers\": {\n \"view\": \"By country\",\n \"measure\": \"amount\",\n \"materiality\": {\n \"mode\": \"abs\",\n \"abs\": 300000\n },\n \"top_n\": 15,\n \"others_label\": \"Other items\"\n },\n \"drill\": {\n \"top_n\": 5\n },\n \"commentary\": {\n \"units\": \"M\",\n \"decimals\": 1,\n \"verify_tag\": \"[TO VERIFY]\",\n \"sign_style\": \"plus_minus\",\n \"currency_symbol\": \"$\",\n \"forbidden_terms\": [],\n \"max_line_words\": 35\n },\n \"controls\": [\n {\n \"id\": \"required_columns\",\n \"severity\": \"stop\"\n },\n {\n \"id\": \"periods_present\",\n \"severity\": \"stop\"\n },\n {\n \"id\": \"no_duplicate_periods_across_files\",\n \"severity\": \"stop\"\n },\n {\n \"id\": \"new_or_removed_members\",\n \"severity\": \"warn\"\n },\n {\n \"id\": \"drivers_reconcile\",\n \"severity\": \"stop\"\n },\n {\n \"id\": \"flags_sum_to_rows\",\n \"severity\": \"stop\"\n },\n {\n \"id\": \"sections_reconcile\",\n \"severity\": \"stop\"\n },\n {\n \"id\": \"join_unmatched_keys\",\n \"severity\": \"warn\"\n },\n {\n \"id\": \"join_fanout\",\n \"severity\": \"stop\"\n },\n {\n \"id\": \"classification_coverage\",\n \"severity\": \"warn\",\n \"params\": {\n \"minimum_percentage\": 95\n }\n },\n {\n \"id\": \"partial_period_used\",\n \"severity\": \"warn\"\n }\n ],\n \"value_rules\": {\n \"source\": \"column\",\n \"null_as_zero\": true,\n \"flip_sign_when\": []\n },\n \"joins\": [],\n \"classification\": null\n },\n \"confidence\": \"high\",\n \"rationale\": \"Defined the primary additive sum measure using Functional_Net to support movement reconciliation in the By country view, while preserving all existing drivers, settings, and mandatory controls.\",\n \"questions\": [],\n \"warnings\": [],\n \"summary\": \"Set up the amount measure using Functional_Net, grouped by Country, explaining movements above $300,000 for up to fifteen items.\",\n \"changes\": [\n {\n \"setting\": \"Amount column\",\n \"from\": \"Not set\",\n \"to\": \"Sum of Functional_Net\",\n \"reason\": \"Provide an additive measure for country variance reconciliation\"\n }\n ]\n}"}}
A9: 8 | B9: 1 | C9: {"timestamp": "2026-10-29T09:23:58.488698+00:00", "response": {"contract_version": "journey-1", "request_id": "c26643b9-f3fc-4a6d-b74e-9cd664f37b04", "step": "write_commentary", "status": "ok", "proposal": {"headline": "Variance commentary by country", "lines": [{"driver_id": "d1", "text": "+$1.0M — United Kingdom. Descriptions include Data centre cooling maintenance / Operational.", "support": "supported", "evidence_refs": ["driver:d1", "text:d1:1"], "claims": [{"type": "observation", "text": "United Kingdom moved by +$1.0M from $2.9M to $3.8M.", "evidence_refs": ["driver:d1"]}, {"type": "observation", "text": "Descriptions include Data centre cooling maintenance / Operational.", "evidence_refs": ["text:d1:1"]}]}, {"driver_id": "d2", "text": "+$0.9M — Germany. Descriptions include Emergency generator servicing / Operational.", "support": "supported", "evidence_refs": ["driver:d2", "text:d2:1"], "claims": [{"type": "observation", "text": "Germany moved by +$0.9M from $1.9M to $2.7M.", "evidence_refs": ["driver:d2"]}, {"type": "observation", "text": "Descriptions include Emergency generator servicing / Operational.", "evidence_refs": ["text:d2:1"]}]}, {"driver_id": "d3", "text": "-$0.6M — Netherlands. Descriptions include Preventive maintenance contract / Operational.", "support": "supported", "evidence_refs": ["driver:d3", "text:d3:1"], "claims": [{"type": "observation", "text": "Netherlands moved by -$0.6M from $2.2M to $1.6M.", "evidence_refs": ["driver:d3"]}, {"type": "observation", "text": "Descriptions include Preventive maintenance contract / Operational.", "evidence_refs": ["text:d3:1"]}]}, {"driver_id": "others", "text": "+$0.2M — Other items. Remaining movements below the materiality threshold, grouped by the engine.", "support": "supported", "evidence_refs": ["driver:others"], "claims": [{"type": "observation", "text": "Other items moved by +$0.2M from $2.6M to $2.8M.", "evidence_refs": ["driver:others"]}]}], "others_summary": ""}, "confidence": "high", "rationale": "Drafted factual commentary for all four movements using exact tokens, observed descriptions, and cited evidence references.", "questions": [], "warnings": [], "summary": "Commentary drafted for United Kingdom, Germany, Netherlands, and Other items.", "changes": [], "validation": {"ok": true, "issues": [], "line_results": [{"driver_id": "d1", "ok": true, "issues": []}, {"driver_id": "d2", "ok": true, "issues": []}, {"driver_id": "d3", "ok": true, "issues": []}, {"driver_id": "others", "ok": true, "issues": []}]}, "applied": false}}
A10: 9 | B10: 1 | C10: {"transport_attempt": {"request_id": "c26643b9-f3fc-4a6d-b74e-9cd664f37b04", "step": "write_commentary", "envelope_size": 14589, "duration": 12.117, "status": "ok", "response": "{\n \"contract_version\": \"journey-1\",\n \"request_id\": \"c26643b9-f3fc-4a6d-b74e-9cd664f37b04\",\n \"step\": \"write_commentary\",\n \"status\": \"ok\",\n \"proposal\": {\n \"headline\": \"Variance commentary by country\",\n \"lines\": [\n {\n \"driver_id\": \"d1\",\n \"text\": \"+$1.0M — United Kingdom. Descriptions include Data centre cooling maintenance / Operational.\",\n \"support\": \"supported\",\n \"evidence_refs\": [\n \"driver:d1\",\n \"text:d1:1\"\n ],\n \"claims\": [\n {\n \"type\": \"observation\",\n \"text\": \"United Kingdom moved by +$1.0M from $2.9M to $3.8M.\",\n \"evidence_refs\": [\n \"driver:d1\"\n ]\n },\n {\n \"type\": \"observation\",\n \"text\": \"Descriptions include Data centre cooling maintenance / Operational.\",\n \"evidence_refs\": [\n \"text:d1:1\"\n ]\n }\n ]\n },\n {\n \"driver_id\": \"d2\",\n \"text\": \"+$0.9M — Germany. Descriptions include Emergency generator servicing / Operational.\",\n \"support\": \"supported\",\n \"evidence_refs\": [\n \"driver:d2\",\n \"text:d2:1\"\n ],\n \"claims\": [\n {\n \"type\": \"observation\",\n \"text\": \"Germany moved by +$0.9M from $1.9M to $2.7M.\",\n \"evidence_refs\": [\n \"driver:d2\"\n ]\n },\n {\n \"type\": \"observation\",\n \"text\": \"Descriptions include Emergency generator servicing / Operational.\",\n \"evidence_refs\": [\n \"text:d2:1\"\n ]\n }\n ]\n },\n {\n \"driver_id\": \"d3\",\n \"text\": \"-$0.6M — Netherlands. Descriptions include Preventive maintenance contract / Operational.\",\n \"support\": \"supported\",\n \"evidence_refs\": [\n \"driver:d3\",\n \"text:d3:1\"\n ],\n \"claims\": [\n {\n \"type\": \"observation\",\n \"text\": \"Netherlands moved by -$0.6M from $2.2M to $1.6M.\",\n \"evidence_refs\": [\n \"driver:d3\"\n ]\n },\n {\n \"type\": \"observation\",\n \"text\": \"Descriptions include Preventive maintenance contract / Operational.\",\n \"evidence_refs\": [\n \"text:d3:1\"\n ]\n }\n ]\n },\n {\n \"driver_id\": \"others\",\n \"text\": \"+$0.2M — Other items. Remaining movements below the materiality threshold, grouped by the engine.\",\n \"support\": \"supported\",\n \"evidence_refs\": [\n \"driver:others\"\n ],\n \"claims\": [\n {\n \"type\": \"observation\",\n \"text\": \"Other items moved by +$0.2M from $2.6M to $2.8M.\",\n \"evidence_refs\": [\n \"driver:others\"\n ]\n }\n ]\n }\n ],\n \"others_summary\": \"\"\n },\n \"confidence\": \"high\",\n \"rationale\": \"Drafted factual commentary for all four movements using exact tokens, observed descriptions, and cited evidence references.\",\n \"questions\": [],\n \"warnings\": [],\n \"summary\": \"Commentary drafted for United Kingdom, Germany, Netherlands, and Other items.\",\n \"changes\": []\n}"}}

Sheet FluxSpec
A1: FluxSpec (JSON)
A2: {
A3: "spec_version": "2.0",
A4: "preset": {
A5: "id": "generic_flux",
A6: "version": "1.0.0"
A7: },
A8: "flux_name": "Untitled analysis",
A9: "sources": {
A10: "lookups": {
A11: "open_po": {
A12: "files": [
... A224: }
